<?xml version='1.0'?>
<sdf version='1.7'>
  <world name='default'>
    <gui fullscreen='0'>
      <camera name='user_camera'>
        <pose>2.55307 -3.4005 2.7847 0 0.385796 2.23617</pose>
        <view_controller>orbit</view_controller>
        <projection_type>perspective</projection_type>
      </camera>
    </gui>
    <gravity>0 0 -9.81</gravity>
    <physics name='default_physics' default='0' type='ode'>
      <max_step_size>0.001</max_step_size>
      <real_time_factor>1</real_time_factor>
      <real_time_update_rate>1000</real_time_update_rate>
    </physics>
    <scene>
      <ambient>0.4 0.4 0.4 1</ambient>
      <background>0.7 0.7 0.7 1</background>
      <shadows>1</shadows>
    </scene>
    <light name='sun' type='directional'>
      <cast_shadows>1</cast_shadows>
      <pose>0 0 10 0 -0 0</pose>
      <diffuse>0.8 0.8 0.8 1</diffuse>
      <specular>0.2 0.2 0.2 1</specular>
      <attenuation>
        <range>1000</range>
        <constant>0.9</constant>
        <linear>0.01</linear>
        <quadratic>0.001</quadratic>
      </attenuation>
      <direction>-0.5 0.1 -0.9</direction>
      <spot>
        <inner_angle>0</inner_angle>
        <outer_angle>0</outer_angle>
        <falloff>0</falloff>
      </spot>
    </light>
    <model name='ground_plane'>
      <static>1</static>
      <link name='link'>
        <collision name='collision'>
          <geometry>
            <plane>
              <normal>0 0 1</normal>
              <size>100 100</size>
            </plane>
          </geometry>
          <surface>
            <contact>
              <collide_bitmask>65535</collide_bitmask>
              <ode/>
            </contact>
            <friction>
              <ode>
                <mu>100</mu>
                <mu2>50</mu2>
              </ode>
              <torsional>
                <ode/>
              </torsional>
            </friction>
            <bounce/>
          </surface>
          <max_contacts>10</max_contacts>
        </collision>
        <visual name='visual'>
          <cast_shadows>0</cast_shadows>
          <geometry>
            <plane>
              <normal>0 0 1</normal>
              <size>100 100</size>
            </plane>
          </geometry>
          <material>
            <script>
              <uri>file://media/materials/scripts/gazebo.material</uri>
              <name>Gazebo/Grey</name>
            </script>
          </material>
        </visual>
        <self_collide>0</self_collide>
        <enable_wind>0</enable_wind>
        <kinematic>0</kinematic>
      </link>
      <pose>0 0 0 0 -0 0</pose>
    </model>
    <model name='xarm_base'>
      <static>1</static>
      <link name='top_plate'>
        <pose>0 0 0.755 0 -0 0</pose>
        <collision name='top_plate_collision'>
          <geometry>
            <box>
              <size>0.25 0.25 0.04</size>
            </box>
          </geometry>
          <surface>
            <contact>
              <collide_bitmask>1</collide_bitmask>
              <ode/>
            </contact>
            <bounce/>
            <friction>
              <torsional>
                <ode/>
              </torsional>
              <ode/>
            </friction>
          </surface>
          <max_contacts>10</max_contacts>
        </collision>
        <visual name='top_plate_visual'>
          <geometry>
            <box>
              <size>0.25 0.25 0.04</size>
            </box>
          </geometry>
          <material>
            <script>
              <uri>file://media/materials/scripts/gazebo.material</uri>
              <name>Gazebo/Grey</name>
            </script>
          </material>
        </visual>
        <self_collide>0</self_collide>
        <enable_wind>0</enable_wind>
        <kinematic>0</kinematic>
      </link>
      <link name='leg1'>
        <pose>0.1 0.1 0.285 0 -0 0</pose>
        <collision name='leg1_collision'>
          <geometry>
            <box>
              <size>0.04 0.04 0.965</size>
            </box>
          </geometry>
          <max_contacts>10</max_contacts>
          <surface>
            <contact>
              <ode/>
            </contact>
            <bounce/>
            <friction>
              <torsional>
                <ode/>
              </torsional>
              <ode/>
            </friction>
          </surface>
        </collision>
        <visual name='leg1_visual'>
          <geometry>
            <box>
              <size>0.04 0.04 0.965</size>
            </box>
          </geometry>
          <material>
            <script>
              <uri>file://media/materials/scripts/gazebo.material</uri>
              <name>Gazebo/Grey</name>
            </script>
          </material>
        </visual>
        <self_collide>0</self_collide>
        <enable_wind>0</enable_wind>
        <kinematic>0</kinematic>
      </link>
      <link name='leg2'>
        <pose>-0.1 0.1 0.285 0 -0 0</pose>
        <collision name='leg2_collision'>
          <geometry>
            <box>
              <size>0.04 0.04 0.965</size>
            </box>
          </geometry>
          <max_contacts>10</max_contacts>
          <surface>
            <contact>
              <ode/>
            </contact>
            <bounce/>
            <friction>
              <torsional>
                <ode/>
              </torsional>
              <ode/>
            </friction>
          </surface>
        </collision>
        <visual name='leg2_visual'>
          <geometry>
            <box>
              <size>0.04 0.04 0.965</size>
            </box>
          </geometry>
          <material>
            <script>
              <uri>file://media/materials/scripts/gazebo.material</uri>
              <name>Gazebo/Grey</name>
            </script>
          </material>
        </visual>
        <self_collide>0</self_collide>
        <enable_wind>0</enable_wind>
        <kinematic>0</kinematic>
      </link>
      <link name='leg3'>
        <pose>0.1 -0.1 0.285 0 -0 0</pose>
        <collision name='leg3_collision'>
          <geometry>
            <box>
              <size>0.04 0.04 0.965</size>
            </box>
          </geometry>
          <max_contacts>10</max_contacts>
          <surface>
            <contact>
              <ode/>
            </contact>
            <bounce/>
            <friction>
              <torsional>
                <ode/>
              </torsional>
              <ode/>
            </friction>
          </surface>
        </collision>
        <visual name='leg3_visual'>
          <geometry>
            <box>
              <size>0.04 0.04 0.965</size>
            </box>
          </geometry>
          <material>
            <script>
              <uri>file://media/materials/scripts/gazebo.material</uri>
              <name>Gazebo/Grey</name>
            </script>
          </material>
        </visual>
        <self_collide>0</self_collide>
        <enable_wind>0</enable_wind>
        <kinematic>0</kinematic>
      </link>
      <link name='leg4'>
        <pose>-0.1 -0.1 0.285 0 -0 0</pose>
        <collision name='leg4_collision'>
          <geometry>
            <box>
              <size>0.04 0.04 0.965</size>
            </box>
          </geometry>
          <max_contacts>10</max_contacts>
          <surface>
            <contact>
              <ode/>
            </contact>
            <bounce/>
            <friction>
              <torsional>
                <ode/>
              </torsional>
              <ode/>
            </friction>
          </surface>
        </collision>
        <visual name='leg4_visual'>
          <geometry>
            <box>
              <size>0.04 0.04 0.965</size>
            </box>
          </geometry>
          <material>
            <script>
              <uri>file://media/materials/scripts/gazebo.material</uri>
              <name>Gazebo/Grey</name>
            </script>
          </material>
        </visual>
        <self_collide>0</self_collide>
        <enable_wind>0</enable_wind>
        <kinematic>0</kinematic>
      </link>
    </model>
    <model name='cafe_table'>
      <static>1</static>
      <frame name='cafe_table::__model__' attached_to='cafe_table::link'>
        <pose relative_to='__model__'>0.7 0 0 0 -0 0</pose>
      </frame>
      <static>1</static>
      <link name='cafe_table::link'>
        <collision name='surface'>
          <pose>0 0 0.755 0 -0 0</pose>
          <geometry>
            <box>
              <size>0.913 0.913 0.04</size>
            </box>
          </geometry>
          <max_contacts>10</max_contacts>
          <surface>
            <contact>
              <ode/>
            </contact>
            <bounce/>
            <friction>
              <torsional>
                <ode/>
              </torsional>
              <ode/>
            </friction>
          </surface>
        </collision>
        <collision name='column'>
          <pose>0 0 0.37 0 -0 0</pose>
          <geometry>
            <box>
              <size>0.042 0.042 0.74</size>
            </box>
          </geometry>
          <max_contacts>10</max_contacts>
          <surface>
            <contact>
              <ode/>
            </contact>
            <bounce/>
            <friction>
              <torsional>
                <ode/>
              </torsional>
              <ode/>
            </friction>
          </surface>
        </collision>
        <collision name='base'>
          <pose>0 0 0.02 0 -0 0</pose>
          <geometry>
            <box>
              <size>0.56 0.56 0.04</size>
            </box>
          </geometry>
          <max_contacts>10</max_contacts>
          <surface>
            <contact>
              <ode/>
            </contact>
            <bounce/>
            <friction>
              <torsional>
                <ode/>
              </torsional>
              <ode/>
            </friction>
          </surface>
        </collision>
        <visual name='visual'>
          <geometry>
            <mesh>
              <uri>model://cafe_table/meshes/cafe_table.dae</uri>
            </mesh>
          </geometry>
        </visual>
        <pose relative_to='cafe_table::__model__'>0 0 0 0 -0 0</pose>
        <self_collide>0</self_collide>
        <enable_wind>0</enable_wind>
        <kinematic>0</kinematic>
      </link>
    </model>
    <magnetic_field>6e-06 2.3e-05 -4.2e-05</magnetic_field>
    <atmosphere type='adiabatic'/>
    <wind/>
    <spherical_coordinates>
      <surface_model>EARTH_WGS84</surface_model>
      <latitude_deg>0</latitude_deg>
      <longitude_deg>0</longitude_deg>
      <elevation>0</elevation>
      <heading_deg>0</heading_deg>
    </spherical_coordinates>
    <model name='xarm6'>
      <joint name='world_joint' type='fixed'>
        <pose relative_to='__model__'>0 0 0 0 -0 0</pose>
        <parent>world</parent>
        <child>link_base</child>
      </joint>
      <link name='link_base'>
        <pose relative_to='world_joint'>0 0 0 0 -0 0</pose>
        <inertial>
          <pose>0.047724 0.006966 0.165442 0 -0 0</pose>
          <mass>2.9</mass>
          <inertia>
            <ixx>0.245626</ixx>
            <ixy>-0.0130179</ixy>
            <ixz>-0.139018</ixz>
            <iyy>0.330887</iyy>
            <iyz>-0.0202904</iyz>
            <izz>0.115286</izz>
          </inertia>
        </inertial>
        <collision name='link_base_collision'>
          <pose>0 0 0 0 -0 0</pose>
          <geometry>
            <mesh>
              <scale>1 1 1</scale>
              <uri>/home/snehith/catkin_ws/src/xarm_ros_mod/xarm_description/meshes/xarm6/visual/base.stl</uri>
            </mesh>
          </geometry>
          <surface>
            <contact>
              <ode/>
            </contact>
            <friction>
              <ode/>
              <torsional>
                <ode/>
              </torsional>
            </friction>
            <bounce/>
          </surface>
          <max_contacts>10</max_contacts>
        </collision>
        <collision name='link_base_fixed_joint_lump__link_camera_collision_1'>
          <pose>0.692 0.001 1.17 3.14159 1.57079 3.14159</pose>
          <geometry>
            <sphere>
              <radius>0.02</radius>
            </sphere>
          </geometry>
          <surface>
            <contact>
              <ode/>
            </contact>
            <friction>
              <ode/>
              <torsional>
                <ode/>
              </torsional>
            </friction>
            <bounce/>
          </surface>
          <max_contacts>10</max_contacts>
        </collision>
        <collision name='link_base_fixed_joint_lump__new_camera_link_collision_2'>
          <pose>0.692 0.201 1.17 3.14159 1.57079 3.14159</pose>
          <geometry>
            <sphere>
              <radius>0.02</radius>
            </sphere>
          </geometry>
          <surface>
            <contact>
              <ode/>
            </contact>
            <friction>
              <ode/>
              <torsional>
                <ode/>
              </torsional>
            </friction>
            <bounce/>
          </surface>
          <max_contacts>10</max_contacts>
        </collision>
        <visual name='link_base_visual'>
          <pose>0 0 0 0 -0 0</pose>
          <geometry>
            <mesh>
              <scale>1 1 1</scale>
              <uri>/home/snehith/catkin_ws/src/xarm_ros_mod/xarm_description/meshes/xarm6/visual/base.stl</uri>
            </mesh>
          </geometry>
        </visual>
        <visual name='link_base_fixed_joint_lump__link_camera_visual_1'>
          <pose>0.692 0.001 1.17 3.14159 1.57079 3.14159</pose>
          <geometry>
            <sphere>
              <radius>0.02</radius>
            </sphere>
          </geometry>
          <material>
            <script>
              <name>Gazebo/Black</name>
              <uri>file://media/materials/scripts/gazebo.material</uri>
            </script>
          </material>
        </visual>
        <visual name='link_base_fixed_joint_lump__new_camera_link_visual_2'>
          <pose>0.692 0.201 1.17 3.14159 1.57079 3.14159</pose>
          <geometry>
            <sphere>
              <radius>0.02</radius>
            </sphere>
          </geometry>
        </visual>
        <self_collide>1</self_collide>
        <sensor name='xarm_camera_node' type='camera'>
          <update_rate>10</update_rate>
          <camera name='head'>
            <horizontal_fov>0.994838</horizontal_fov>
            <image>
              <width>1920</width>
              <height>1080</height>
              <format>B8G8R8</format>
            </image>
            <clip>
              <near>0.02</near>
              <far>300</far>
            </clip>
            <noise>
              <type>gaussian</type>
              <mean>0</mean>
              <stddev>0.007</stddev>
            </noise>
            <lens>
              <intrinsics>
                <fx>1493</fx>
                <fy>1493</fy>
                <cx>960</cx>
                <cy>540</cy>
                <s>0</s>
              </intrinsics>
              <type>stereographic</type>
              <scale_to_hfov>1</scale_to_hfov>
            </lens>
          </camera>
          <plugin name='gazebo_camera' filename='libgazebo_ros_camera.so'>
            <alwaysOn>1</alwaysOn>
            <updateRate>0.0</updateRate>
            <cameraName>/camera</cameraName>
            <imageTopicName>image_raw</imageTopicName>
            <cameraInfoTopicName>camera_info</cameraInfoTopicName>
            <frameName>camera_link</frameName>
            <hackBaseline>0.07</hackBaseline>
            <distortionK1>0.0</distortionK1>
            <distortionK2>0.0</distortionK2>
            <distortionK3>0.0</distortionK3>
            <distortionT1>0.0</distortionT1>
            <distortionT2>0.0</distortionT2>
            <robotNamespace>/</robotNamespace>
          </plugin>
          <pose>0.692 0.001 1.17 3.14159 1.57079 3.14159</pose>
        </sensor>
        <sensor name='camera2' type='camera'>
          <update_rate>10</update_rate>
          <camera name='head'>
            <horizontal_fov>0.994838</horizontal_fov>
            <image>
              <width>1920</width>
              <height>1080</height>
              <format>B8G8R8</format>
            </image>
            <clip>
              <near>0.02</near>
              <far>300</far>
            </clip>
            <noise>
              <type>gaussian</type>
              <mean>0</mean>
              <stddev>0.007</stddev>
            </noise>
            <lens>
              <intrinsics>
                <fx>1493</fx>
                <fy>1493</fy>
                <cx>960</cx>
                <cy>540</cy>
                <s>0</s>
              </intrinsics>
              <type>stereographic</type>
              <scale_to_hfov>1</scale_to_hfov>
            </lens>
          </camera>
          <plugin name='gazebo_camera' filename='libgazebo_ros_camera.so'>
            <alwaysOn>1</alwaysOn>
            <updateRate>0.0</updateRate>
            <cameraName>/camera2</cameraName>
            <imageTopicName>image_raw</imageTopicName>
            <cameraInfoTopicName>camera_info</cameraInfoTopicName>
            <frameName>new_camera_link</frameName>
            <hackBaseline>0.07</hackBaseline>
            <distortionK1>0.0</distortionK1>
            <distortionK2>0.0</distortionK2>
            <distortionK3>0.0</distortionK3>
            <distortionT1>0.0</distortionT1>
            <distortionT2>0.0</distortionT2>
            <robotNamespace>/</robotNamespace>
          </plugin>
          <pose>0.692 0.201 1.17 3.14159 1.57079 3.14159</pose>
        </sensor>
        <enable_wind>0</enable_wind>
        <kinematic>0</kinematic>
      </link>
      <joint name='joint1' type='revolute'>
        <pose relative_to='link_base'>0 0 0.267 0 -0 0</pose>
        <parent>link_base</parent>
        <child>link1</child>
        <axis>
          <xyz>0 0 1</xyz>
          <limit>
            <lower>-3.11018</lower>
            <upper>3.11018</upper>
            <effort>50</effort>
            <velocity>3.14</velocity>
          </limit>
          <dynamics>
            <damping>1</damping>
            <friction>1</friction>
            <spring_reference>0</spring_reference>
            <spring_stiffness>0</spring_stiffness>
          </dynamics>
        </axis>
      </joint>
      <link name='link1'>
        <pose relative_to='joint1'>0 0 0 0 -0 0</pose>
        <inertial>
          <pose>-0.002 0.02692 -0.01332 0 -0 0</pose>
          <mass>2.16</mass>
          <inertia>
            <ixx>0.00539427</ixx>
            <ixy>1.095e-05</ixy>
            <ixz>1.635e-06</ixz>
            <iyy>0.0048979</iyy>
            <iyz>0.000793</iyz>
            <izz>0.00311573</izz>
          </inertia>
        </inertial>
        <collision name='link1_collision'>
          <pose>0 0 0 0 -0 0</pose>
          <geometry>
            <mesh>
              <scale>1 1 1</scale>
              <uri>/home/snehith/catkin_ws/src/xarm_ros_mod/xarm_description/meshes/xarm6/visual/link1.stl</uri>
            </mesh>
          </geometry>
          <surface>
            <contact>
              <ode/>
            </contact>
            <friction>
              <ode/>
              <torsional>
                <ode/>
              </torsional>
            </friction>
            <bounce/>
          </surface>
          <max_contacts>10</max_contacts>
        </collision>
        <visual name='link1_visual'>
          <pose>0 0 0 0 -0 0</pose>
          <geometry>
            <mesh>
              <scale>1 1 1</scale>
              <uri>/home/snehith/catkin_ws/src/xarm_ros_mod/xarm_description/meshes/xarm6/visual/link1.stl</uri>
            </mesh>
          </geometry>
        </visual>
        <self_collide>1</self_collide>
        <enable_wind>0</enable_wind>
        <kinematic>0</kinematic>
      </link>
      <joint name='joint2' type='revolute'>
        <pose relative_to='link1'>0 0 0 -1.5708 0 0</pose>
        <parent>link1</parent>
        <child>link2</child>
        <axis>
          <xyz>0 0 1</xyz>
          <limit>
            <lower>-2.059</lower>
            <upper>2.0944</upper>
            <effort>50</effort>
            <velocity>3.14</velocity>
          </limit>
          <dynamics>
            <damping>1</damping>
            <friction>1</friction>
            <spring_reference>0</spring_reference>
            <spring_stiffness>0</spring_stiffness>
          </dynamics>
        </axis>
      </joint>
      <link name='link2'>
        <pose relative_to='joint2'>0 0 0 0 -0 0</pose>
        <inertial>
          <pose>0.03531 -0.21398 0.03386 0 -0 0</pose>
          <mass>1.71</mass>
          <inertia>
            <ixx>0.0248674</ixx>
            <ixy>-0.00430651</ixy>
            <ixz>-0.00067797</ixz>
            <iyy>0.00485548</iyy>
            <iyz>0.00457245</iyz>
            <izz>0.0238783</izz>
          </inertia>
        </inertial>
        <collision name='link2_collision'>
          <pose>0 0 0 0 -0 0</pose>
          <geometry>
            <mesh>
              <scale>1 1 1</scale>
              <uri>/home/snehith/catkin_ws/src/xarm_ros_mod/xarm_description/meshes/xarm6/visual/link2.stl</uri>
            </mesh>
          </geometry>
          <surface>
            <contact>
              <ode/>
            </contact>
            <friction>
              <ode/>
              <torsional>
                <ode/>
              </torsional>
            </friction>
            <bounce/>
          </surface>
          <max_contacts>10</max_contacts>
        </collision>
        <visual name='link2_visual'>
          <pose>0 0 0 0 -0 0</pose>
          <geometry>
            <mesh>
              <scale>1 1 1</scale>
              <uri>/home/snehith/catkin_ws/src/xarm_ros_mod/xarm_description/meshes/xarm6/visual/link2.stl</uri>
            </mesh>
          </geometry>
        </visual>
        <self_collide>1</self_collide>
        <enable_wind>0</enable_wind>
        <kinematic>0</kinematic>
      </link>
      <joint name='joint3' type='revolute'>
        <pose relative_to='link2'>0.0535 -0.2845 0 0 -0 0</pose>
        <parent>link2</parent>
        <child>link3</child>
        <axis>
          <xyz>0 0 1</xyz>
          <limit>
            <lower>-3.11018</lower>
            <upper>0.19198</upper>
            <effort>32</effort>
            <velocity>3.14</velocity>
          </limit>
          <dynamics>
            <damping>1</damping>
            <friction>1</friction>
            <spring_reference>0</spring_reference>
            <spring_stiffness>0</spring_stiffness>
          </dynamics>
        </axis>
      </joint>
      <link name='link3'>
        <pose relative_to='joint3'>0 0 0 0 -0 0</pose>
        <inertial>
          <pose>0.06781 0.10749 0.01457 0 -0 0</pose>
          <mass>1.384</mass>
          <inertia>
            <ixx>0.0053694</ixx>
            <ixy>0.0014185</ixy>
            <ixz>-0.00092094</ixz>
            <iyy>0.0032423</iyy>
            <iyz>-0.00169178</iyz>
            <izz>0.00501731</izz>
          </inertia>
        </inertial>
        <collision name='link3_collision'>
          <pose>0 0 0 0 -0 0</pose>
          <geometry>
            <mesh>
              <scale>1 1 1</scale>
              <uri>/home/snehith/catkin_ws/src/xarm_ros_mod/xarm_description/meshes/xarm6/visual/link3.stl</uri>
            </mesh>
          </geometry>
          <surface>
            <contact>
              <ode/>
            </contact>
            <friction>
              <ode/>
              <torsional>
                <ode/>
              </torsional>
            </friction>
            <bounce/>
          </surface>
          <max_contacts>10</max_contacts>
        </collision>
        <visual name='link3_visual'>
          <pose>0 0 0 0 -0 0</pose>
          <geometry>
            <mesh>
              <scale>1 1 1</scale>
              <uri>/home/snehith/catkin_ws/src/xarm_ros_mod/xarm_description/meshes/xarm6/visual/link3.stl</uri>
            </mesh>
          </geometry>
        </visual>
        <self_collide>1</self_collide>
        <enable_wind>0</enable_wind>
        <kinematic>0</kinematic>
      </link>
      <joint name='joint4' type='revolute'>
        <pose relative_to='link3'>0.0775 0.3425 0 -1.5708 0 0</pose>
        <parent>link3</parent>
        <child>link4</child>
        <axis>
          <xyz>0 0 1</xyz>
          <limit>
            <lower>-3.11018</lower>
            <upper>3.11018</upper>
            <effort>32</effort>
            <velocity>3.14</velocity>
          </limit>
          <dynamics>
            <damping>1</damping>
            <friction>1</friction>
            <spring_reference>0</spring_reference>
            <spring_stiffness>0</spring_stiffness>
          </dynamics>
        </axis>
      </joint>
      <link name='link4'>
        <pose relative_to='joint4'>0 0 0 0 -0 0</pose>
        <inertial>
          <pose>-0.00021 0.02578 -0.02538 0 -0 0</pose>
          <mass>1.115</mass>
          <inertia>
            <ixx>0.00439263</ixx>
            <ixy>5.028e-05</ixy>
            <ixz>1.374e-05</ixz>
            <iyy>0.0040077</iyy>
            <iyz>0.00045338</iyz>
            <izz>0.00110321</izz>
          </inertia>
        </inertial>
        <collision name='link4_collision'>
          <pose>0 0 0 0 -0 0</pose>
          <geometry>
            <mesh>
              <scale>1 1 1</scale>
              <uri>/home/snehith/catkin_ws/src/xarm_ros_mod/xarm_description/meshes/xarm6/visual/link4.stl</uri>
            </mesh>
          </geometry>
          <surface>
            <contact>
              <ode/>
            </contact>
            <friction>
              <ode/>
              <torsional>
                <ode/>
              </torsional>
            </friction>
            <bounce/>
          </surface>
          <max_contacts>10</max_contacts>
        </collision>
        <visual name='link4_visual'>
          <pose>0 0 0 0 -0 0</pose>
          <geometry>
            <mesh>
              <scale>1 1 1</scale>
              <uri>/home/snehith/catkin_ws/src/xarm_ros_mod/xarm_description/meshes/xarm6/visual/link4.stl</uri>
            </mesh>
          </geometry>
        </visual>
        <self_collide>1</self_collide>
        <enable_wind>0</enable_wind>
        <kinematic>0</kinematic>
      </link>
      <joint name='joint5' type='revolute'>
        <pose relative_to='link4'>0 0 0 1.5708 -0 0</pose>
        <parent>link4</parent>
        <child>link5</child>
        <axis>
          <xyz>0 0 1</xyz>
          <limit>
            <lower>-1.69297</lower>
            <upper>3.11018</upper>
            <effort>32</effort>
            <velocity>3.14</velocity>
          </limit>
          <dynamics>
            <damping>1</damping>
            <friction>1</friction>
            <spring_reference>0</spring_reference>
            <spring_stiffness>0</spring_stiffness>
          </dynamics>
        </axis>
      </joint>
      <link name='link5'>
        <pose relative_to='joint5'>0 0 0 0 -0 0</pose>
        <inertial>
          <pose>0.05428 0.01781 0.00543 0 -0 0</pose>
          <mass>1.275</mass>
          <inertia>
            <ixx>0.00120276</ixx>
            <ixy>0.000492428</ixy>
            <ixz>-0.00039147</ixz>
            <iyy>0.0022876</iyy>
            <iyz>-0.0001235</iyz>
            <izz>0.0026866</izz>
          </inertia>
        </inertial>
        <collision name='link5_collision'>
          <pose>0 0 0 0 -0 0</pose>
          <geometry>
            <mesh>
              <scale>1 1 1</scale>
              <uri>/home/snehith/catkin_ws/src/xarm_ros_mod/xarm_description/meshes/xarm6/visual/link5.stl</uri>
            </mesh>
          </geometry>
          <surface>
            <contact>
              <ode/>
            </contact>
            <friction>
              <ode/>
              <torsional>
                <ode/>
              </torsional>
            </friction>
            <bounce/>
          </surface>
          <max_contacts>10</max_contacts>
        </collision>
        <visual name='link5_visual'>
          <pose>0 0 0 0 -0 0</pose>
          <geometry>
            <mesh>
              <scale>1 1 1</scale>
              <uri>/home/snehith/catkin_ws/src/xarm_ros_mod/xarm_description/meshes/xarm6/visual/link5.stl</uri>
            </mesh>
          </geometry>
        </visual>
        <self_collide>1</self_collide>
        <enable_wind>0</enable_wind>
        <kinematic>0</kinematic>
      </link>
      <joint name='joint6' type='revolute'>
        <pose relative_to='link5'>0.076 0.097 0 -1.5708 0 0</pose>
        <parent>link5</parent>
        <child>link6</child>
        <axis>
          <xyz>0 0 1</xyz>
          <limit>
            <lower>-3.11018</lower>
            <upper>3.11018</upper>
            <effort>20</effort>
            <velocity>3.14</velocity>
          </limit>
          <dynamics>
            <damping>1</damping>
            <friction>1</friction>
            <spring_reference>0</spring_reference>
            <spring_stiffness>0</spring_stiffness>
          </dynamics>
        </axis>
      </joint>
      <link name='link6'>
        <pose relative_to='joint6'>0 0 0 0 -0 0</pose>
        <inertial>
          <pose>-0.000545 -0.001431 0.038342 0 -0 0</pose>
          <mass>0.65116</mass>
          <inertia>
            <ixx>0.000818795</ixx>
            <ixy>2.44297e-07</ixy>
            <ixz>6.08903e-06</ixz>
            <iyy>0.000680747</iyy>
            <iyz>2.08511e-06</iyz>
            <izz>0.000336739</izz>
          </inertia>
        </inertial>
        <collision name='link6_collision'>
          <pose>0 0 0 0 -0 0</pose>
          <geometry>
            <mesh>
              <scale>1 1 1</scale>
              <uri>/home/snehith/catkin_ws/src/xarm_ros_mod/xarm_description/meshes/collision/end_tool.STL</uri>
            </mesh>
          </geometry>
          <surface>
            <contact>
              <ode/>
            </contact>
            <friction>
              <ode/>
              <torsional>
                <ode/>
              </torsional>
            </friction>
            <bounce/>
          </surface>
          <max_contacts>10</max_contacts>
        </collision>
        <collision name='link6_fixed_joint_lump__xarm_gripper_base_link_collision_1'>
          <pose>0 0 0 0 -0 0</pose>
          <geometry>
            <mesh>
              <scale>1 1 1</scale>
              <uri>/home/snehith/catkin_ws/src/xarm_ros_mod/xarm_gripper/meshes/base_link_collision.STL</uri>
            </mesh>
          </geometry>
          <surface>
            <contact>
              <ode/>
            </contact>
            <friction>
              <ode/>
              <torsional>
                <ode/>
              </torsional>
            </friction>
            <bounce/>
          </surface>
          <max_contacts>10</max_contacts>
        </collision>
        <visual name='link6_visual'>
          <pose>0 0 0 0 -0 0</pose>
          <geometry>
            <mesh>
              <scale>1 1 1</scale>
              <uri>/home/snehith/catkin_ws/src/xarm_ros_mod/xarm_description/meshes/xarm6/visual/link6.stl</uri>
            </mesh>
          </geometry>
        </visual>
        <visual name='link6_fixed_joint_lump__xarm_gripper_base_link_visual_1'>
          <pose>0 0 0 0 -0 0</pose>
          <geometry>
            <mesh>
              <scale>1 1 1</scale>
              <uri>/home/snehith/catkin_ws/src/xarm_ros_mod/xarm_gripper/meshes/base_link.STL</uri>
            </mesh>
          </geometry>
        </visual>
        <self_collide>0</self_collide>
        <enable_wind>0</enable_wind>
        <kinematic>0</kinematic>
      </link>
      <joint name='drive_joint' type='revolute'>
        <pose relative_to='link6'>0 0.035 0.059098 0 -0 0</pose>
        <parent>link6</parent>
        <child>left_outer_knuckle</child>
        <axis>
          <xyz>1 0 0</xyz>
          <limit>
            <lower>0</lower>
            <upper>0.85</upper>
            <effort>50</effort>
            <velocity>2</velocity>
          </limit>
          <dynamics>
            <spring_reference>0</spring_reference>
            <spring_stiffness>0</spring_stiffness>
          </dynamics>
        </axis>
      </joint>
      <link name='left_outer_knuckle'>
        <pose relative_to='drive_joint'>0 0 0 0 -0 0</pose>
        <inertial>
          <pose>0 0.021559 0.015181 0 -0 0</pose>
          <mass>0.033618</mass>
          <inertia>
            <ixx>1.9111e-05</ixx>
            <ixy>-1.8803e-17</ixy>
            <ixz>-1.1002e-17</ixz>
            <iyy>6.6256e-06</iyy>
            <iyz>-7.3008e-06</iyz>
            <izz>1.3185e-05</izz>
          </inertia>
        </inertial>
        <collision name='left_outer_knuckle_collision'>
          <pose>0 0 0 0 -0 0</pose>
          <geometry>
            <mesh>
              <scale>1 1 1</scale>
              <uri>/home/snehith/catkin_ws/src/xarm_ros_mod/xarm_gripper/meshes/left_outer_knuckle.STL</uri>
            </mesh>
          </geometry>
          <surface>
            <contact>
              <ode/>
            </contact>
            <friction>
              <ode/>
              <torsional>
                <ode/>
              </torsional>
            </friction>
            <bounce/>
          </surface>
          <max_contacts>10</max_contacts>
        </collision>
        <visual name='left_outer_knuckle_visual'>
          <pose>0 0 0 0 -0 0</pose>
          <geometry>
            <mesh>
              <scale>1 1 1</scale>
              <uri>/home/snehith/catkin_ws/src/xarm_ros_mod/xarm_gripper/meshes/left_outer_knuckle.STL</uri>
            </mesh>
          </geometry>
        </visual>
        <self_collide>0</self_collide>
        <enable_wind>0</enable_wind>
        <kinematic>0</kinematic>
      </link>
      <joint name='left_finger_joint' type='revolute'>
        <pose relative_to='left_outer_knuckle'>0 0.035465 0.042039 0 -0 0</pose>
        <parent>left_outer_knuckle</parent>
        <child>left_finger</child>
        <axis>
          <xyz>-1 0 0</xyz>
          <limit>
            <lower>0</lower>
            <upper>0.85</upper>
            <effort>50</effort>
            <velocity>2</velocity>
          </limit>
          <dynamics>
            <spring_reference>0</spring_reference>
            <spring_stiffness>0</spring_stiffness>
          </dynamics>
        </axis>
      </joint>
      <link name='left_finger'>
        <pose relative_to='left_finger_joint'>0 0 0 0 -0 0</pose>
        <inertial>
          <pose>-0 -0.016413 0.029258 0 -0 0</pose>
          <mass>0.048304</mass>
          <inertia>
            <ixx>1.7493e-05</ixx>
            <ixy>-4.2156e-19</ixy>
            <ixz>6.9164e-18</ixz>
            <iyy>1.7225e-05</iyy>
            <iyz>4.6433e-06</iyz>
            <izz>5.1466e-06</izz>
          </inertia>
        </inertial>
        <collision name='left_finger_collision'>
          <pose>0 0 0 0 -0 0</pose>
          <geometry>
            <mesh>
              <scale>1 1 1</scale>
              <uri>/home/snehith/catkin_ws/src/xarm_ros_mod/xarm_gripper/meshes/left_finger.STL</uri>
            </mesh>
          </geometry>
          <surface>
            <contact>
              <ode/>
            </contact>
            <friction>
              <ode>
                <mu>100.01</mu>
                <mu2>100.01</mu2>
                <minDepth>0.003</minDepth>
                <maxVel>0</maxVel>
              </ode>
              <torsional>
                <ode/>
              </torsional>
            </friction>
            <bounce/>
          </surface>
          <max_contacts>10</max_contacts>
        </collision>
        <visual name='left_finger_visual'>
          <pose>0 0 0 0 -0 0</pose>
          <geometry>
            <mesh>
              <scale>1 1 1</scale>
              <uri>/home/snehith/catkin_ws/src/xarm_ros_mod/xarm_gripper/meshes/left_finger.STL</uri>
            </mesh>
          </geometry>
        </visual>
        <self_collide>0</self_collide>
        <enable_wind>0</enable_wind>
        <kinematic>0</kinematic>
      </link>
      <joint name='left_inner_knuckle_joint' type='revolute'>
        <pose relative_to='link6'>0 0.02 0.074098 0 -0 0</pose>
        <parent>link6</parent>
        <child>left_inner_knuckle</child>
        <axis>
          <xyz>1 0 0</xyz>
          <limit>
            <lower>0</lower>
            <upper>0.85</upper>
            <effort>50</effort>
            <velocity>2</velocity>
          </limit>
          <dynamics>
            <spring_reference>0</spring_reference>
            <spring_stiffness>0</spring_stiffness>
          </dynamics>
        </axis>
      </joint>
      <link name='left_inner_knuckle'>
        <pose relative_to='left_inner_knuckle_joint'>0 0 0 0 -0 0</pose>
        <inertial>
          <pose>2e-06 0.022047 0.026133 0 -0 0</pose>
          <mass>0.0230126</mass>
          <inertia>
            <ixx>6.0949e-06</ixx>
            <ixy>6.06651e-11</ixy>
            <ixz>7.19103e-11</ixz>
            <iyy>6.01955e-06</iyy>
            <iyz>-2.75317e-06</iyz>
            <izz>5.07862e-06</izz>
          </inertia>
        </inertial>
        <collision name='left_inner_knuckle_collision'>
          <pose>0 0 0 0 -0 0</pose>
          <geometry>
            <mesh>
              <scale>1 1 1</scale>
              <uri>/home/snehith/catkin_ws/src/xarm_ros_mod/xarm_gripper/meshes/left_inner_knuckle.STL</uri>
            </mesh>
          </geometry>
          <surface>
            <contact>
              <ode/>
            </contact>
            <friction>
              <ode/>
              <torsional>
                <ode/>
              </torsional>
            </friction>
            <bounce/>
          </surface>
          <max_contacts>10</max_contacts>
        </collision>
        <visual name='left_inner_knuckle_visual'>
          <pose>0 0 0 0 -0 0</pose>
          <geometry>
            <mesh>
              <scale>1 1 1</scale>
              <uri>/home/snehith/catkin_ws/src/xarm_ros_mod/xarm_gripper/meshes/left_inner_knuckle.STL</uri>
            </mesh>
          </geometry>
        </visual>
        <self_collide>0</self_collide>
        <enable_wind>0</enable_wind>
        <kinematic>0</kinematic>
      </link>
      <joint name='right_inner_knuckle_joint' type='revolute'>
        <pose relative_to='link6'>0 -0.02 0.074098 0 -0 0</pose>
        <parent>link6</parent>
        <child>right_inner_knuckle</child>
        <axis>
          <xyz>-1 0 0</xyz>
          <limit>
            <lower>0</lower>
            <upper>0.85</upper>
            <effort>50</effort>
            <velocity>2</velocity>
          </limit>
          <dynamics>
            <spring_reference>0</spring_reference>
            <spring_stiffness>0</spring_stiffness>
          </dynamics>
        </axis>
      </joint>
      <link name='right_inner_knuckle'>
        <pose relative_to='right_inner_knuckle_joint'>0 0 0 0 -0 0</pose>
        <inertial>
          <pose>2e-06 -0.022047 0.026133 0 -0 0</pose>
          <mass>0.023013</mass>
          <inertia>
            <ixx>6.0949e-06</ixx>
            <ixy>-6.0665e-11</ixy>
            <ixz>7.191e-11</ixz>
            <iyy>6.0197e-06</iyy>
            <iyz>2.7531e-06</iyz>
            <izz>5.0784e-06</izz>
          </inertia>
        </inertial>
        <collision name='right_inner_knuckle_collision'>
          <pose>0 0 0 0 -0 0</pose>
          <geometry>
            <mesh>
              <scale>1 1 1</scale>
              <uri>/home/snehith/catkin_ws/src/xarm_ros_mod/xarm_gripper/meshes/right_inner_knuckle.STL</uri>
            </mesh>
          </geometry>
          <surface>
            <contact>
              <ode/>
            </contact>
            <friction>
              <ode/>
              <torsional>
                <ode/>
              </torsional>
            </friction>
            <bounce/>
          </surface>
          <max_contacts>10</max_contacts>
        </collision>
        <visual name='right_inner_knuckle_visual'>
          <pose>0 0 0 0 -0 0</pose>
          <geometry>
            <mesh>
              <scale>1 1 1</scale>
              <uri>/home/snehith/catkin_ws/src/xarm_ros_mod/xarm_gripper/meshes/right_inner_knuckle.STL</uri>
            </mesh>
          </geometry>
        </visual>
        <self_collide>0</self_collide>
        <enable_wind>0</enable_wind>
        <kinematic>0</kinematic>
      </link>
      <joint name='right_outer_knuckle_joint' type='revolute'>
        <pose relative_to='link6'>0 -0.035 0.059098 0 -0 0</pose>
        <parent>link6</parent>
        <child>right_outer_knuckle</child>
        <axis>
          <xyz>-1 0 0</xyz>
          <limit>
            <lower>0</lower>
            <upper>0.85</upper>
            <effort>50</effort>
            <velocity>2</velocity>
          </limit>
          <dynamics>
            <spring_reference>0</spring_reference>
            <spring_stiffness>0</spring_stiffness>
          </dynamics>
        </axis>
      </joint>
      <link name='right_outer_knuckle'>
        <pose relative_to='right_outer_knuckle_joint'>0 0 0 0 -0 0</pose>
        <inertial>
          <pose>-0 -0.021559 0.015181 0 -0 0</pose>
          <mass>0.033618</mass>
          <inertia>
            <ixx>1.9111e-05</ixx>
            <ixy>-1.8789e-17</ixy>
            <ixz>1.0986e-17</ixz>
            <iyy>6.6256e-06</iyy>
            <iyz>7.3008e-06</iyz>
            <izz>1.3185e-05</izz>
          </inertia>
        </inertial>
        <collision name='right_outer_knuckle_collision'>
          <pose>0 0 0 0 -0 0</pose>
          <geometry>
            <mesh>
              <scale>1 1 1</scale>
              <uri>/home/snehith/catkin_ws/src/xarm_ros_mod/xarm_gripper/meshes/right_outer_knuckle.STL</uri>
            </mesh>
          </geometry>
          <surface>
            <contact>
              <ode/>
            </contact>
            <friction>
              <ode/>
              <torsional>
                <ode/>
              </torsional>
            </friction>
            <bounce/>
          </surface>
          <max_contacts>10</max_contacts>
        </collision>
        <visual name='right_outer_knuckle_visual'>
          <pose>0 0 0 0 -0 0</pose>
          <geometry>
            <mesh>
              <scale>1 1 1</scale>
              <uri>/home/snehith/catkin_ws/src/xarm_ros_mod/xarm_gripper/meshes/right_outer_knuckle.STL</uri>
            </mesh>
          </geometry>
        </visual>
        <self_collide>0</self_collide>
        <enable_wind>0</enable_wind>
        <kinematic>0</kinematic>
      </link>
      <joint name='right_finger_joint' type='revolute'>
        <pose relative_to='right_outer_knuckle'>0 -0.035465 0.042039 0 -0 0</pose>
        <parent>right_outer_knuckle</parent>
        <child>right_finger</child>
        <axis>
          <xyz>1 0 0</xyz>
          <limit>
            <lower>0</lower>
            <upper>0.85</upper>
            <effort>50</effort>
            <velocity>2</velocity>
          </limit>
          <dynamics>
            <spring_reference>0</spring_reference>
            <spring_stiffness>0</spring_stiffness>
          </dynamics>
        </axis>
      </joint>
      <link name='right_finger'>
        <pose relative_to='right_finger_joint'>0 0 0 0 -0 0</pose>
        <inertial>
          <pose>0 0.016413 0.029258 0 -0 0</pose>
          <mass>0.048304</mass>
          <inertia>
            <ixx>1.7493e-05</ixx>
            <ixy>-5.0014e-19</ixy>
            <ixz>-7.5079e-18</ixz>
            <iyy>1.7225e-05</iyy>
            <iyz>-4.6435e-06</iyz>
            <izz>5.1466e-06</izz>
          </inertia>
        </inertial>
        <collision name='right_finger_collision'>
          <pose>0 0 0 0 -0 0</pose>
          <geometry>
            <mesh>
              <scale>1 1 1</scale>
              <uri>/home/snehith/catkin_ws/src/xarm_ros_mod/xarm_gripper/meshes/right_finger.STL</uri>
            </mesh>
          </geometry>
          <surface>
            <contact>
              <ode/>
            </contact>
            <friction>
              <ode>
                <mu>1.01</mu>
                <mu2>1.01</mu2>
                <minDepth>0.003</minDepth>
                <maxVel>0</maxVel>
              </ode>
              <torsional>
                <ode/>
              </torsional>
            </friction>
            <bounce/>
          </surface>
          <max_contacts>10</max_contacts>
        </collision>
        <visual name='right_finger_visual'>
          <pose>0 0 0 0 -0 0</pose>
          <geometry>
            <mesh>
              <scale>1 1 1</scale>
              <uri>/home/snehith/catkin_ws/src/xarm_ros_mod/xarm_gripper/meshes/right_finger.STL</uri>
            </mesh>
          </geometry>
        </visual>
        <self_collide>0</self_collide>
        <enable_wind>0</enable_wind>
        <kinematic>0</kinematic>
      </link>
      <plugin name='gazebo_ros_control' filename='libgazebo_ros_control.so'>
        <robotNamespace>/xarm</robotNamespace>
        <robotSimType>gazebo_ros_control/DefaultRobotHWSim</robotSimType>
        <legacyModeNS>1</legacyModeNS>
      </plugin>
      <plugin name='gazebo_grasp_fix' filename='libgazebo_grasp_fix.so'>
        <arm>
          <arm_name>xarm_gripper</arm_name>
          <palm_link>link6</palm_link>
          <gripper_link>left_inner_knuckle</gripper_link>
          <gripper_link>right_inner_knuckle</gripper_link>
          <gripper_link>left_finger</gripper_link>
          <gripper_link>right_finger</gripper_link>
        </arm>
        <forces_angle_tolerance>100</forces_angle_tolerance>
        <update_rate>10</update_rate>
        <grip_count_threshold>2</grip_count_threshold>
        <max_grip_count>3</max_grip_count>
        <release_tolerance>0.0198</release_tolerance>
        <disable_collisions_on_attach>0</disable_collisions_on_attach>
        <contact_topic>__default_topic__</contact_topic>
        <robotNamespace>/</robotNamespace>
      </plugin>
      <plugin name='left_finger_jointmimic_joint_plugin' filename='libroboticsgroup_upatras_gazebo_mimic_joint_plugin.so'>
        <joint>drive_joint</joint>
        <mimicJoint>left_finger_joint</mimicJoint>
        <multiplier>1.0</multiplier>
        <offset>0</offset>
        <sensitiveness>0.0</sensitiveness>
        <maxEffort>10.0</maxEffort>
        <robotNamespace>/</robotNamespace>
      </plugin>
      <plugin name='left_inner_knuckle_jointmimic_joint_plugin' filename='libroboticsgroup_upatras_gazebo_mimic_joint_plugin.so'>
        <joint>drive_joint</joint>
        <mimicJoint>left_inner_knuckle_joint</mimicJoint>
        <multiplier>1.0</multiplier>
        <offset>0</offset>
        <sensitiveness>0.0</sensitiveness>
        <maxEffort>10.0</maxEffort>
        <robotNamespace>/</robotNamespace>
      </plugin>
      <plugin name='right_outer_knuckle_jointmimic_joint_plugin' filename='libroboticsgroup_upatras_gazebo_mimic_joint_plugin.so'>
        <joint>drive_joint</joint>
        <mimicJoint>right_outer_knuckle_joint</mimicJoint>
        <multiplier>1.0</multiplier>
        <offset>0</offset>
        <sensitiveness>0.0</sensitiveness>
        <maxEffort>10.0</maxEffort>
        <robotNamespace>/</robotNamespace>
      </plugin>
      <plugin name='right_finger_jointmimic_joint_plugin' filename='libroboticsgroup_upatras_gazebo_mimic_joint_plugin.so'>
        <joint>drive_joint</joint>
        <mimicJoint>right_finger_joint</mimicJoint>
        <multiplier>1.0</multiplier>
        <offset>0</offset>
        <sensitiveness>0.0</sensitiveness>
        <maxEffort>10.0</maxEffort>
        <robotNamespace>/</robotNamespace>
      </plugin>
      <static>0</static>
      <plugin name='right_inner_knuckle_jointmimic_joint_plugin' filename='libroboticsgroup_upatras_gazebo_mimic_joint_plugin.so'>
        <joint>drive_joint</joint>
        <mimicJoint>right_inner_knuckle_joint</mimicJoint>
        <multiplier>1.0</multiplier>
        <offset>0</offset>
        <sensitiveness>0.0</sensitiveness>
        <maxEffort>10.0</maxEffort>
        <robotNamespace>/</robotNamespace>
      </plugin>
      <pose>0 0 0.775 0 -0 0</pose>
    </model>
    <state world_name='default'>
      <sim_time>2765 876000000</sim_time>
      <real_time>455 855418784</real_time>
      <wall_time>1677305950 683451185</wall_time>
      <iterations>135500</iterations>
      <model name='bowl'>
        <pose>0.808867 -0.025223 0.818885 1.33611 1.20723 2.03999</pose>
        <scale>1.35 1.35 1.35</scale>
        <link name='body'>
          <pose>0.808867 -0.025223 0.818885 1.33611 1.20723 2.03999</pose>
          <velocity>0 0 0 0 -0 0</velocity>
          <acceleration>0 0 0 0 -0 0</acceleration>
          <wrench>0 0 0 0 -0 0</wrench>
        </link>
      </model>
      <model name='cafe_table'>
        <pose>0.202439 -0.074491 -0.002919 0 -0 0</pose>
        <scale>1 1 1</scale>
        <link name='cafe_table::link'>
          <pose>0.902439 -0.074491 -0.002919 0 -0 0</pose>
          <velocity>0 0 0 0 -0 0</velocity>
          <acceleration>0 0 0 0 -0 0</acceleration>
          <wrench>0 0 0 0 -0 0</wrench>
        </link>
      </model>
      <model name='ground_plane'>
        <pose>0 0 0 0 -0 0</pose>
        <scale>1 1 1</scale>
        <link name='link'>
          <pose>0 0 0 0 -0 0</pose>
          <velocity>0 0 0 0 -0 0</velocity>
          <acceleration>0 0 0 0 -0 0</acceleration>
          <wrench>0 0 0 0 -0 0</wrench>
        </link>
      </model>
      <model name='spoon_plus_box_1_small'>
        <pose>0.756971 -0.31601 0.849488 -0.044049 -0.125391 3.03727</pose>
        <scale>1 1 1</scale>
        <link name='body'>
          <pose>0.756971 -0.31601 0.849488 -0.044049 -0.125391 3.03727</pose>
          <velocity>-0.001982 0.000979 -0.004957 -0.020943 -0.03038 0.002379</velocity>
          <acceleration>-1.82752 0.917949 -5.16026 0.283224 -1.29895 2.03974</acceleration>
          <wrench>-0.438604 0.220308 -1.23846 0 -0 0</wrench>
        </link>
        <link name='box_link'>
          <pose>0.534118 -0.299423 0.940287 -0.092424 1.07769 2.95029</pose>
          <velocity>-0.007041 0.001014 2.5e-05 -0.02298 -0.054232 0.003029</velocity>
          <acceleration>-8.35809 1.15157 -3.6494 -1.2998 0.467617 2.66711</acceleration>
          <wrench>-0.094446 0.013013 -0.041238 0 -0 0</wrench>
        </link>
        <link name='pic1::link'>
          <pose>0.578749 -0.300375 0.94083 -0.092432 1.07773 2.95029</pose>
          <velocity>-0.005022 0.001241 -0.010605 -0.021376 -0.031466 0.003104</velocity>
          <acceleration>-4.3916 1.22029 -12.9704 -2.75007 1.52964 -0.547792</acceleration>
          <wrench>-4e-06 1e-06 -1.3e-05 0 -0 0</wrench>
        </link>
      </model>
      <model name='spoon_plus_box_2_small'>
        <pose>0.759863 0.261672 0.832251 -0.037763 -0.129373 3.01281</pose>
        <scale>1 1 1</scale>
        <link name='body'>
          <pose>0.759863 0.261672 0.832251 -0.037763 -0.129373 3.01281</pose>
          <velocity>-0.001981 0.001084 -0.004791 -0.010112 -0.034824 -0.003272</velocity>
          <acceleration>-1.87562 1.00021 -5.09415 2.31532 -1.21584 2.3573</acceleration>
          <wrench>-0.450149 0.240049 -1.2226 0 -0 0</wrench>
        </link>
        <link name='box_link'>
          <pose>0.537898 0.284045 0.923979 -0.078664 1.07423 2.93874</pose>
          <velocity>-0.007186 0.001284 -0.001015 -0.013613 -0.057583 -0.006456</velocity>
          <acceleration>-8.20102 1.64461 -3.92261 -3.01058 -1.34964 0.24728</acceleration>
          <wrench>-0.092672 0.018584 -0.044326 0 -0 0</wrench>
        </link>
        <link name='pic2::link'>
          <pose>0.582496 0.28204 0.924322 -0.078672 1.07426 2.93873</pose>
          <velocity>-0.005231 0.001842 -0.011208 -0.010976 -0.035282 -0.00527</velocity>
          <acceleration>-4.20181 1.9088 -12.9029 -0.532559 0.456609 0.700914</acceleration>
          <wrench>-4e-06 2e-06 -1.3e-05 0 -0 0</wrench>
        </link>
      </model>
      <model name='standard_bowl'>
        <pose>0.815786 -0.322256 0.77278 1.57787 -0 0</pose>
        <scale>1 1 1</scale>
        <link name='body'>
          <pose>0.815786 -0.322256 0.77278 1.57787 -0 0</pose>
          <velocity>0 0 0 0 -0 0</velocity>
          <acceleration>0 0 0 0 -0 0</acceleration>
          <wrench>0 0 0 0 -0 0</wrench>
        </link>
      </model>
      <model name='standard_bowl_clone'>
        <pose>0.819518 0.255476 0.755333 1.57787 -0 0</pose>
        <scale>1 1 1</scale>
        <link name='body'>
          <pose>0.819518 0.255476 0.755333 1.57787 -0 0</pose>
          <velocity>0 0 0 0 -0 0</velocity>
          <acceleration>0 0 0 0 -0 0</acceleration>
          <wrench>0 0 0 0 -0 0</wrench>
        </link>
      </model>
      <model name='xarm6'>
        <pose>-0 -0 0.775 0 -0 0</pose>
        <scale>1 1 1</scale>
        <link name='left_finger'>
          <pose>0.329853 -0.069647 1.05995 2.60747 -1.57014 0.533978</pose>
          <velocity>0.000225 -3.2e-05 -0.003123 8.3e-05 0.010015 -0.000312</velocity>
          <acceleration>-0.000439 0.000155 0.001523 -0.431833 -0.096275 0.012193</acceleration>
          <wrench>-2.1e-05 7e-06 7.4e-05 0 -0 0</wrench>
        </link>
        <link name='left_inner_knuckle'>
          <pose>0.302117 -0.020029 1.05996 2.98411 -1.57063 0.177445</pose>
          <velocity>0.000252 -1.7e-05 -0.00284 0.000128 0.00998 -0.000705</velocity>
          <acceleration>-0.001222 -0.002117 0.002815 0.016642 -0.056346 0.012221</acceleration>
          <wrench>-2.8e-05 -4.9e-05 6.5e-05 0 -0 0</wrench>
        </link>
        <link name='left_outer_knuckle'>
          <pose>0.287115 -0.035027 1.05996 2.67048 -1.56999 0.491059</pose>
          <velocity>0.000244 -9e-06 -0.002693 7.7e-05 0.010038 -0.000525</velocity>
          <acceleration>-0.00043 -0.001474 0.001473 -1.47547 0.045524 2.71881</acceleration>
          <wrench>-1.4e-05 -5e-05 5e-05 0 -0 0</wrench>
        </link>
        <link name='link1'>
          <pose>-0 0 1.042 -1e-06 -1.4e-05 -4.1e-05</pose>
          <velocity>0 2e-06 -1.1e-05 -1e-05 6e-06 0.00057</velocity>
          <acceleration>0.000434 0.003603 -0.023364 -0.020604 0.012422 -0.018226</acceleration>
          <wrench>0.000937 0.007783 -0.050466 0 -0 0</wrench>
        </link>
        <link name='link2'>
          <pose>2e-06 -0 1.042 -1.57079 9.2e-05 -5.6e-05</pose>
          <velocity>-1e-06 1e-06 -1e-05 -1.1e-05 0.008582 0.000578</velocity>
          <acceleration>-0.007563 0.007429 -0.020341 -0.889629 0.610902 -2.10538</acceleration>
          <wrench>-0.012933 0.012704 -0.034784 0 -0 0</wrench>
        </link>
        <link name='link3'>
          <pose>0.053527 -5e-06 1.32649 -1.57079 4.9e-05 -4.2e-05</pose>
          <velocity>0.002442 3.5e-05 -0.000467 -1.2e-05 0.00858 0.000564</velocity>
          <acceleration>-0.003727 0.003947 -0.012905 0.049324 -0.431636 0.62945</acceleration>
          <wrench>-0.005158 0.005463 -0.017861 0 -0 0</wrench>
        </link>
        <link name='link4'>
          <pose>0.131011 -5e-06 0.983989 -3.14158 5.8e-05 -0.000132</pose>
          <velocity>-0.000496 7.5e-05 -0.001131 -1.4e-05 0.008573 -0.000551</velocity>
          <acceleration>0.001241 -0.001184 -0.010413 -0.04086 -0.039422 -0.024522</acceleration>
          <wrench>0.001384 -0.00132 -0.01161 0 -0 0</wrench>
        </link>
        <link name='link5'>
          <pose>0.131012 -5e-06 0.983988 -1.49195 -1.57066 -0.078989</pose>
          <velocity>-0.000496 7.5e-05 -0.001131 -9e-06 0.009987 -0.000547</velocity>
          <acceleration>0.000135 -0.000849 -0.009066 -0.001981 -0.060904 0.394087</acceleration>
          <wrench>0.000172 -0.001082 -0.011559 0 -0 0</wrench>
        </link>
        <link name='link6'>
          <pose>0.228022 -1.9e-05 1.05997 3.07025 -1.57065 0.071201</pose>
          <velocity>0.000263 2.3e-05 -0.002099 0.000123 0.009983 -0.000546</velocity>
          <acceleration>-0.000767 -0.001793 -0.002117 0.517308 -0.047514 0.010326</acceleration>
          <wrench>-0.0005 -0.001168 -0.001379 0 -0 0</wrench>
        </link>
        <link name='link_base'>
          <pose>-0 -0 0.775 0 -0 0</pose>
          <velocity>-0 0 -1.2e-05 -6e-06 -0 -8e-06</velocity>
          <acceleration>-0.000374 0.001981 -0.024389 -0.011196 -0.000203 -0.016278</acceleration>
          <wrench>-0.001084 0.005744 -0.070727 0 -0 0</wrench>
        </link>
        <link name='right_finger'>
          <pose>0.329873 0.06958 1.05995 -2.63103 -1.57016 -0.510706</pose>
          <velocity>0.000302 -3.4e-05 -0.003106 0.000158 0.009997 -0.000298</velocity>
          <acceleration>-0.000118 -0.001593 0.002193 0.24387 -0.088865 0.005539</acceleration>
          <wrench>-6e-06 -7.7e-05 0.000106 0 -0 0</wrench>
        </link>
        <link name='right_inner_knuckle'>
          <pose>0.302123 0.01997 1.05996 3.09491 -1.57064 0.02645</pose>
          <velocity>0.000274 -1.7e-05 -0.002835 0.000119 0.009979 -0.000479</velocity>
          <acceleration>-0.000159 -0.002374 0.001442 -0.094293 -0.107178 -0.039062</acceleration>
          <wrench>-4e-06 -5.5e-05 3.3e-05 0 -0 0</wrench>
        </link>
        <link name='right_outer_knuckle'>
          <pose>0.287125 0.034973 1.05996 -3.01536 -1.57067 -0.146464</pose>
          <velocity>0.000281 -9e-06 -0.002684 0.000117 0.009944 -0.000586</velocity>
          <acceleration>-0.000411 -0.00187 -0.00018 -0.346434 -0.516464 -0.063222</acceleration>
          <wrench>-1.4e-05 -6.3e-05 -6e-06 0 -0 0</wrench>
        </link>
      </model>
      <model name='xarm_base'>
        <pose>0 0 0 0 -0 0</pose>
        <scale>1 1 1</scale>
        <link name='leg1'>
          <pose>0.1 0.1 0.285 0 -0 0</pose>
          <velocity>0 0 0 0 -0 0</velocity>
          <acceleration>0 0 0 0 -0 0</acceleration>
          <wrench>0 0 0 0 -0 0</wrench>
        </link>
        <link name='leg2'>
          <pose>-0.1 0.1 0.285 0 -0 0</pose>
          <velocity>0 0 0 0 -0 0</velocity>
          <acceleration>0 0 0 0 -0 0</acceleration>
          <wrench>0 0 0 0 -0 0</wrench>
        </link>
        <link name='leg3'>
          <pose>0.1 -0.1 0.285 0 -0 0</pose>
          <velocity>0 0 0 0 -0 0</velocity>
          <acceleration>0 0 0 0 -0 0</acceleration>
          <wrench>0 0 0 0 -0 0</wrench>
        </link>
        <link name='leg4'>
          <pose>-0.1 -0.1 0.285 0 -0 0</pose>
          <velocity>0 0 0 0 -0 0</velocity>
          <acceleration>0 0 0 0 -0 0</acceleration>
          <wrench>0 0 0 0 -0 0</wrench>
        </link>
        <link name='top_plate'>
          <pose>0 0 0.755 0 -0 0</pose>
          <velocity>0 0 0 0 -0 0</velocity>
          <acceleration>0 0 0 0 -0 0</acceleration>
          <wrench>0 0 0 0 -0 0</wrench>
        </link>
      </model>
      <light name='sun'>
        <pose>0 0 10 0 -0 0</pose>
      </light>
    </state>
    <model name='bowl'>
      <static>1</static>
      <link name='body'>
        <visual name='visual'>
          <geometry>
            <mesh>
              <uri>model://bowl/meshes/poly.dae</uri>
              <scale>1.35 1.35 1.35</scale>
            </mesh>
          </geometry>
        </visual>
        <inertial>
          <mass>0.024</mass>
        </inertial>
        <self_collide>0</self_collide>
        <enable_wind>0</enable_wind>
        <kinematic>0</kinematic>
      </link>
      <pose>0.232873 -0.364585 0 0 -0 0</pose>
    </model>
    <model name='standard_bowl'>
      <static>1</static>
      <link name='body'>
        <visual name='visual'>
          <geometry>
            <mesh>
              <uri>model://standard_bowl/meshes/standard_bowl.dae</uri>
            </mesh>
          </geometry>
        </visual>
        <collision name='collision'>
          <geometry>
            <mesh>
              <uri>model://standard_bowl/meshes/standard_bowl.dae</uri>
            </mesh>
          </geometry>
          <max_contacts>10</max_contacts>
          <surface>
            <contact>
              <ode/>
            </contact>
            <bounce/>
            <friction>
              <torsional>
                <ode/>
              </torsional>
              <ode/>
            </friction>
          </surface>
        </collision>
        <inertial>
          <mass>0.024</mass>
          <inertia>
            <ixx>6.23397e-06</ixx>
            <ixy>-2.11425e-15</ixy>
            <ixz>3.48224e-14</ixz>
            <iyy>6.23397e-06</iyy>
            <iyz>-6.38861e-14</iyz>
            <izz>9.58827e-06</izz>
          </inertia>
        </inertial>
        <self_collide>0</self_collide>
        <enable_wind>0</enable_wind>
        <kinematic>0</kinematic>
      </link>
      <pose>1.23214 -0.055267 0 0 -0 0</pose>
    </model>
    <model name='standard_bowl_clone'>
      <static>1</static>
      <link name='body'>
        <visual name='visual'>
          <geometry>
            <mesh>
              <uri>model://standard_bowl/meshes/standard_bowl.dae</uri>
            </mesh>
          </geometry>
        </visual>
        <collision name='collision'>
          <geometry>
            <mesh>
              <uri>model://standard_bowl/meshes/standard_bowl.dae</uri>
            </mesh>
          </geometry>
          <max_contacts>10</max_contacts>
          <surface>
            <contact>
              <ode/>
            </contact>
            <bounce/>
            <friction>
              <torsional>
                <ode/>
              </torsional>
              <ode/>
            </friction>
          </surface>
        </collision>
        <inertial>
          <mass>0.024</mass>
          <inertia>
            <ixx>6.23397e-06</ixx>
            <ixy>-2.11425e-15</ixy>
            <ixz>3.48224e-14</ixz>
            <iyy>6.23397e-06</iyy>
            <iyz>-6.38861e-14</iyz>
            <izz>9.58827e-06</izz>
          </inertia>
        </inertial>
        <self_collide>0</self_collide>
        <enable_wind>0</enable_wind>
        <kinematic>0</kinematic>
      </link>
      <pose>0.819518 0.255476 0.755333 1.57787 -0 0</pose>
    </model>
    <model name='spoon_plus_box_1_small'>
      <link name='body'>
        <inertial>
          <mass>0.24</mass>
          <pose>0 0 0 0 -0 0</pose>
          <inertia>
            <ixx>0.003655</ixx>
            <ixy>0</ixy>
            <ixz>0</ixz>
            <iyy>0.003655</iyy>
            <iyz>0</iyz>
            <izz>0.000254</izz>
          </inertia>
        </inertial>
        <self_collide>0</self_collide>
        <enable_wind>0</enable_wind>
        <kinematic>0</kinematic>
        <gravity>1</gravity>
        <pose>0 0 0 0 -0 0</pose>
        <visual name='visual'>
          <geometry>
            <mesh>
              <scale>0.8 0.8 0.8</scale>
              <uri>model://modified_spoon/meshes/spoon_v4.dae</uri>
            </mesh>
          </geometry>
          <pose>0 0 0 0 -0 0</pose>
          <transparency>0</transparency>
          <cast_shadows>1</cast_shadows>
          <material>
            <shader type='pixel'>
              <normal_map>__default__</normal_map>
            </shader>
            <script>
              <name>ModelPreview_1::body::visual_MATERIAL_</name>
              <uri>__default__</uri>
            </script>
            <ambient>0 0 0 1</ambient>
            <diffuse>0 0 0 1</diffuse>
            <specular>0 0 0 1</specular>
            <emissive>0 0 0 1</emissive>
          </material>
        </visual>
        <collision name='collision_2'>
          <laser_retro>0</laser_retro>
          <max_contacts>10</max_contacts>
          <pose>-0.08 0 -0.024 0 -0 0</pose>
          <geometry>
            <box>
              <size>0.1118 0.093883 0.033513</size>
            </box>
          </geometry>
          <surface>
            <friction>
              <ode>
                <mu>1</mu>
                <mu2>1</mu2>
                <fdir1>0 0 0</fdir1>
                <slip1>0</slip1>
                <slip2>0</slip2>
              </ode>
              <torsional>
                <coefficient>1</coefficient>
                <patch_radius>0</patch_radius>
                <surface_radius>0</surface_radius>
                <use_patch_radius>1</use_patch_radius>
                <ode>
                  <slip>0</slip>
                </ode>
              </torsional>
            </friction>
            <bounce>
              <restitution_coefficient>0</restitution_coefficient>
              <threshold>1e+06</threshold>
            </bounce>
            <contact>
              <collide_without_contact>0</collide_without_contact>
              <collide_without_contact_bitmask>1</collide_without_contact_bitmask>
              <collide_bitmask>1</collide_bitmask>
              <ode>
                <soft_cfm>0</soft_cfm>
                <soft_erp>0.2</soft_erp>
                <kp>1e+13</kp>
                <kd>1</kd>
                <max_vel>0.01</max_vel>
                <min_depth>0</min_depth>
              </ode>
              <bullet>
                <split_impulse>1</split_impulse>
                <split_impulse_penetration_threshold>-0.01</split_impulse_penetration_threshold>
                <soft_cfm>0</soft_cfm>
                <soft_erp>0.2</soft_erp>
                <kp>1e+13</kp>
                <kd>1</kd>
              </bullet>
            </contact>
          </surface>
        </collision>
        <collision name='collision_1'>
          <laser_retro>0</laser_retro>
          <max_contacts>10</max_contacts>
          <pose>0.09 -0.007 0.038 0 -0.35 0.01</pose>
          <geometry>
            <box>
              <size>0.2018 0.034883 0.007413</size>
            </box>
          </geometry>
          <surface>
            <friction>
              <ode>
                <mu>1</mu>
                <mu2>1</mu2>
                <fdir1>0 0 0</fdir1>
                <slip1>0</slip1>
                <slip2>0</slip2>
              </ode>
              <torsional>
                <coefficient>1</coefficient>
                <patch_radius>0</patch_radius>
                <surface_radius>0</surface_radius>
                <use_patch_radius>1</use_patch_radius>
                <ode>
                  <slip>0</slip>
                </ode>
              </torsional>
            </friction>
            <bounce>
              <restitution_coefficient>0</restitution_coefficient>
              <threshold>1e+06</threshold>
            </bounce>
            <contact>
              <collide_without_contact>0</collide_without_contact>
              <collide_without_contact_bitmask>1</collide_without_contact_bitmask>
              <collide_bitmask>1</collide_bitmask>
              <ode>
                <soft_cfm>0</soft_cfm>
                <soft_erp>0.2</soft_erp>
                <kp>1e+13</kp>
                <kd>1</kd>
                <max_vel>0.01</max_vel>
                <min_depth>0</min_depth>
              </ode>
              <bullet>
                <split_impulse>1</split_impulse>
                <split_impulse_penetration_threshold>-0.01</split_impulse_penetration_threshold>
                <soft_cfm>0</soft_cfm>
                <soft_erp>0.2</soft_erp>
                <kp>1e+13</kp>
                <kd>1</kd>
              </bullet>
            </contact>
          </surface>
        </collision>
        <collision name='collision'>
          <laser_retro>0</laser_retro>
          <max_contacts>10</max_contacts>
          <pose>-0.015 0 -0.005 0 1.0008 0</pose>
          <geometry>
            <cylinder>
              <radius>0.0101</radius>
              <length>0.022</length>
            </cylinder>
          </geometry>
          <surface>
            <friction>
              <ode>
                <mu>1</mu>
                <mu2>1</mu2>
                <fdir1>0 0 0</fdir1>
                <slip1>0</slip1>
                <slip2>0</slip2>
              </ode>
              <torsional>
                <coefficient>1</coefficient>
                <patch_radius>0</patch_radius>
                <surface_radius>0</surface_radius>
                <use_patch_radius>1</use_patch_radius>
                <ode>
                  <slip>0</slip>
                </ode>
              </torsional>
            </friction>
            <bounce>
              <restitution_coefficient>0</restitution_coefficient>
              <threshold>1e+06</threshold>
            </bounce>
            <contact>
              <collide_without_contact>0</collide_without_contact>
              <collide_without_contact_bitmask>1</collide_without_contact_bitmask>
              <collide_bitmask>1</collide_bitmask>
              <ode>
                <soft_cfm>0</soft_cfm>
                <soft_erp>0.2</soft_erp>
                <kp>1e+13</kp>
                <kd>1</kd>
                <max_vel>0.01</max_vel>
                <min_depth>0</min_depth>
              </ode>
              <bullet>
                <split_impulse>1</split_impulse>
                <split_impulse_penetration_threshold>-0.01</split_impulse_penetration_threshold>
                <soft_cfm>0</soft_cfm>
                <soft_erp>0.2</soft_erp>
                <kp>1e+13</kp>
                <kd>1</kd>
              </bullet>
            </contact>
          </surface>
        </collision>
      </link>
      <link name='box_link'>
        <pose>0.232977 0.003965 0.062401 0 1.20502 0</pose>
        <inertial>
          <mass>0.0113</mass>
          <inertia>
            <ixx>4.17e-06</ixx>
            <ixy>0</ixy>
            <ixz>0</ixz>
            <iyy>4.17e-06</iyy>
            <iyz>0</iyz>
            <izz>4.17e-06</izz>
          </inertia>
          <pose>0 0 0 0 -0 0</pose>
        </inertial>
        <self_collide>0</self_collide>
        <enable_wind>0</enable_wind>
        <kinematic>0</kinematic>
        <visual name='visual'>
          <geometry>
            <box>
              <size>0.04 0.04 0.04</size>
            </box>
          </geometry>
          <material>
            <script>
              <uri>file://media/materials/scripts/gazebo.material</uri>
              <name>Gazebo/Red</name>
            </script>
            <shader type='pixel'/>
          </material>
          <pose>0 0 0 0 -0 0</pose>
          <transparency>0</transparency>
          <cast_shadows>1</cast_shadows>
        </visual>
        <collision name='collision'>
          <laser_retro>0</laser_retro>
          <max_contacts>10</max_contacts>
          <pose>0 0 0 0 -0 0</pose>
          <geometry>
            <box>
              <size>0.04 0.04 0.04</size>
            </box>
          </geometry>
          <surface>
            <friction>
              <ode>
                <mu>1</mu>
                <mu2>1</mu2>
                <fdir1>0 0 0</fdir1>
                <slip1>0</slip1>
                <slip2>0</slip2>
              </ode>
              <torsional>
                <coefficient>1</coefficient>
                <patch_radius>0</patch_radius>
                <surface_radius>0.05</surface_radius>
                <use_patch_radius>0</use_patch_radius>
                <ode>
                  <slip>0</slip>
                </ode>
              </torsional>
            </friction>
            <bounce>
              <restitution_coefficient>0</restitution_coefficient>
              <threshold>1e+06</threshold>
            </bounce>
            <contact>
              <collide_without_contact>0</collide_without_contact>
              <collide_without_contact_bitmask>1</collide_without_contact_bitmask>
              <collide_bitmask>1</collide_bitmask>
              <ode>
                <soft_cfm>0</soft_cfm>
                <soft_erp>0.2</soft_erp>
                <kp>100000</kp>
                <kd>1</kd>
                <max_vel>1</max_vel>
                <min_depth>0.001</min_depth>
              </ode>
              <bullet>
                <split_impulse>1</split_impulse>
                <split_impulse_penetration_threshold>-0.01</split_impulse_penetration_threshold>
                <soft_cfm>0</soft_cfm>
                <soft_erp>0.2</soft_erp>
                <kp>100000</kp>
                <kd>1</kd>
              </bullet>
            </contact>
          </surface>
        </collision>
      </link>
      <link name='pic1::link'>
        <pose>0.1889 0 0.06832 0 1.20502 0</pose>
        <self_collide>0</self_collide>
        <enable_wind>0</enable_wind>
        <kinematic>0</kinematic>
        <gravity>1</gravity>
        <inertial>
          <mass>1e-06</mass>
          <pose>0 0 0 0 -0 0</pose>
          <inertia>
            <ixx>1e-09</ixx>
            <ixy>0</ixy>
            <ixz>0</ixz>
            <iyy>1e-09</iyy>
            <iyz>0</iyz>
            <izz>1e-09</izz>
          </inertia>
        </inertial>
        <visual name='visual'>
          <geometry>
            <mesh>
              <uri>model://pic1/meshes/pic1.dae</uri>
              <scale>0.16 0.16 0.16</scale>
            </mesh>
          </geometry>
          <pose>0 0 0 0 -0 0</pose>
          <transparency>0</transparency>
          <cast_shadows>1</cast_shadows>
          <material>
            <shader type='pixel'/>
          </material>
        </visual>
      </link>
      <joint name='aruco_joint' type='fixed'>
        <parent>body</parent>
        <child>pic1::link</child>
        <pose>0 0 0 0 -0 0</pose>
        <physics>
          <ode>
            <limit>
              <cfm>0</cfm>
              <erp>0.2</erp>
            </limit>
            <suspension>
              <cfm>0</cfm>
              <erp>0.2</erp>
            </suspension>
          </ode>
        </physics>
      </joint>
      <joint name='box_joint' type='fixed'>
        <parent>body</parent>
        <child>box_link</child>
        <pose>0 0 0 0 -0 0</pose>
        <physics>
          <ode>
            <limit>
              <cfm>0</cfm>
              <erp>0.2</erp>
            </limit>
            <suspension>
              <cfm>0</cfm>
              <erp>0.2</erp>
            </suspension>
          </ode>
        </physics>
      </joint>
      <static>0</static>
      <allow_auto_disable>1</allow_auto_disable>
      <pose>0.60617 0.117707 0 0 -0 0</pose>
    </model>
    <model name='spoon_plus_box_2_small'>
      <link name='body'>
        <inertial>
          <mass>0.24</mass>
          <pose>0 0 0 0 -0 0</pose>
          <inertia>
            <ixx>0.003655</ixx>
            <ixy>0</ixy>
            <ixz>0</ixz>
            <iyy>0.003655</iyy>
            <iyz>0</iyz>
            <izz>0.000254</izz>
          </inertia>
        </inertial>
        <self_collide>0</self_collide>
        <enable_wind>0</enable_wind>
        <kinematic>0</kinematic>
        <gravity>1</gravity>
        <pose>0 0 0 0 -0 0</pose>
        <visual name='visual'>
          <geometry>
            <mesh>
              <scale>0.8 0.8 0.8</scale>
              <uri>model://modified_spoon/meshes/spoon_v4.dae</uri>
            </mesh>
          </geometry>
          <pose>0 0 0 0 -0 0</pose>
          <transparency>0</transparency>
          <cast_shadows>1</cast_shadows>
          <material>
            <shader type='pixel'>
              <normal_map>__default__</normal_map>
            </shader>
            <script>
              <name>ModelPreview_1::body::visual_MATERIAL_</name>
              <uri>__default__</uri>
            </script>
            <ambient>0 0 0 1</ambient>
            <diffuse>0 0 0 1</diffuse>
            <specular>0 0 0 1</specular>
            <emissive>0 0 0 1</emissive>
          </material>
        </visual>
        <collision name='collision_2'>
          <laser_retro>0</laser_retro>
          <max_contacts>10</max_contacts>
          <pose>-0.08 0 -0.024 0 -0 0</pose>
          <geometry>
            <box>
              <size>0.1118 0.093883 0.033513</size>
            </box>
          </geometry>
          <surface>
            <friction>
              <ode>
                <mu>1</mu>
                <mu2>1</mu2>
                <fdir1>0 0 0</fdir1>
                <slip1>0</slip1>
                <slip2>0</slip2>
              </ode>
              <torsional>
                <coefficient>1</coefficient>
                <patch_radius>0</patch_radius>
                <surface_radius>0</surface_radius>
                <use_patch_radius>1</use_patch_radius>
                <ode>
                  <slip>0</slip>
                </ode>
              </torsional>
            </friction>
            <bounce>
              <restitution_coefficient>0</restitution_coefficient>
              <threshold>1e+06</threshold>
            </bounce>
            <contact>
              <collide_without_contact>0</collide_without_contact>
              <collide_without_contact_bitmask>1</collide_without_contact_bitmask>
              <collide_bitmask>1</collide_bitmask>
              <ode>
                <soft_cfm>0</soft_cfm>
                <soft_erp>0.2</soft_erp>
                <kp>1e+13</kp>
                <kd>1</kd>
                <max_vel>0.01</max_vel>
                <min_depth>0</min_depth>
              </ode>
              <bullet>
                <split_impulse>1</split_impulse>
                <split_impulse_penetration_threshold>-0.01</split_impulse_penetration_threshold>
                <soft_cfm>0</soft_cfm>
                <soft_erp>0.2</soft_erp>
                <kp>1e+13</kp>
                <kd>1</kd>
              </bullet>
            </contact>
          </surface>
        </collision>
        <collision name='collision_1'>
          <laser_retro>0</laser_retro>
          <max_contacts>10</max_contacts>
          <pose>0.09 -0.007 0.038 0 -0.35 0.01</pose>
          <geometry>
            <box>
              <size>0.2018 0.034883 0.007413</size>
            </box>
          </geometry>
          <surface>
            <friction>
              <ode>
                <mu>1</mu>
                <mu2>1</mu2>
                <fdir1>0 0 0</fdir1>
                <slip1>0</slip1>
                <slip2>0</slip2>
              </ode>
              <torsional>
                <coefficient>1</coefficient>
                <patch_radius>0</patch_radius>
                <surface_radius>0</surface_radius>
                <use_patch_radius>1</use_patch_radius>
                <ode>
                  <slip>0</slip>
                </ode>
              </torsional>
            </friction>
            <bounce>
              <restitution_coefficient>0</restitution_coefficient>
              <threshold>1e+06</threshold>
            </bounce>
            <contact>
              <collide_without_contact>0</collide_without_contact>
              <collide_without_contact_bitmask>1</collide_without_contact_bitmask>
              <collide_bitmask>1</collide_bitmask>
              <ode>
                <soft_cfm>0</soft_cfm>
                <soft_erp>0.2</soft_erp>
                <kp>1e+13</kp>
                <kd>1</kd>
                <max_vel>0.01</max_vel>
                <min_depth>0</min_depth>
              </ode>
              <bullet>
                <split_impulse>1</split_impulse>
                <split_impulse_penetration_threshold>-0.01</split_impulse_penetration_threshold>
                <soft_cfm>0</soft_cfm>
                <soft_erp>0.2</soft_erp>
                <kp>1e+13</kp>
                <kd>1</kd>
              </bullet>
            </contact>
          </surface>
        </collision>
        <collision name='collision'>
          <laser_retro>0</laser_retro>
          <max_contacts>10</max_contacts>
          <pose>-0.015 0 -0.005 0 1.0008 0</pose>
          <geometry>
            <cylinder>
              <radius>0.0101</radius>
              <length>0.022</length>
            </cylinder>
          </geometry>
          <surface>
            <friction>
              <ode>
                <mu>1</mu>
                <mu2>1</mu2>
                <fdir1>0 0 0</fdir1>
                <slip1>0</slip1>
                <slip2>0</slip2>
              </ode>
              <torsional>
                <coefficient>1</coefficient>
                <patch_radius>0</patch_radius>
                <surface_radius>0</surface_radius>
                <use_patch_radius>1</use_patch_radius>
                <ode>
                  <slip>0</slip>
                </ode>
              </torsional>
            </friction>
            <bounce>
              <restitution_coefficient>0</restitution_coefficient>
              <threshold>1e+06</threshold>
            </bounce>
            <contact>
              <collide_without_contact>0</collide_without_contact>
              <collide_without_contact_bitmask>1</collide_without_contact_bitmask>
              <collide_bitmask>1</collide_bitmask>
              <ode>
                <soft_cfm>0</soft_cfm>
                <soft_erp>0.2</soft_erp>
                <kp>1e+13</kp>
                <kd>1</kd>
                <max_vel>0.01</max_vel>
                <min_depth>0</min_depth>
              </ode>
              <bullet>
                <split_impulse>1</split_impulse>
                <split_impulse_penetration_threshold>-0.01</split_impulse_penetration_threshold>
                <soft_cfm>0</soft_cfm>
                <soft_erp>0.2</soft_erp>
                <kp>1e+13</kp>
                <kd>1</kd>
              </bullet>
            </contact>
          </surface>
        </collision>
      </link>
      <link name='box_link'>
        <pose>0.232977 0.003965 0.062401 0 1.20502 0</pose>
        <inertial>
          <mass>0.0113</mass>
          <inertia>
            <ixx>4.17e-06</ixx>
            <ixy>0</ixy>
            <ixz>0</ixz>
            <iyy>4.17e-06</iyy>
            <iyz>0</iyz>
            <izz>4.17e-06</izz>
          </inertia>
          <pose>0 0 0 0 -0 0</pose>
        </inertial>
        <self_collide>0</self_collide>
        <enable_wind>0</enable_wind>
        <kinematic>0</kinematic>
        <visual name='visual'>
          <geometry>
            <box>
              <size>0.04 0.04 0.04</size>
            </box>
          </geometry>
          <material>
            <script>
              <uri>file://media/materials/scripts/gazebo.material</uri>
              <name>Gazebo/Blue</name>
            </script>
            <shader type='pixel'/>
          </material>
          <pose>0 0 0 0 -0 0</pose>
          <transparency>0</transparency>
          <cast_shadows>1</cast_shadows>
        </visual>
        <collision name='collision'>
          <laser_retro>0</laser_retro>
          <max_contacts>10</max_contacts>
          <pose>0 0 0 0 -0 0</pose>
          <geometry>
            <box>
              <size>0.04 0.04 0.04</size>
            </box>
          </geometry>
          <surface>
            <friction>
              <ode>
                <mu>1</mu>
                <mu2>1</mu2>
                <fdir1>0 0 0</fdir1>
                <slip1>0</slip1>
                <slip2>0</slip2>
              </ode>
              <torsional>
                <coefficient>1</coefficient>
                <patch_radius>0</patch_radius>
                <surface_radius>0.05</surface_radius>
                <use_patch_radius>0</use_patch_radius>
                <ode>
                  <slip>0</slip>
                </ode>
              </torsional>
            </friction>
            <bounce>
              <restitution_coefficient>0</restitution_coefficient>
              <threshold>1e+06</threshold>
            </bounce>
            <contact>
              <collide_without_contact>0</collide_without_contact>
              <collide_without_contact_bitmask>1</collide_without_contact_bitmask>
              <collide_bitmask>1</collide_bitmask>
              <ode>
                <soft_cfm>0</soft_cfm>
                <soft_erp>0.2</soft_erp>
                <kp>100000</kp>
                <kd>1</kd>
                <max_vel>1</max_vel>
                <min_depth>0.001</min_depth>
              </ode>
              <bullet>
                <split_impulse>1</split_impulse>
                <split_impulse_penetration_threshold>-0.01</split_impulse_penetration_threshold>
                <soft_cfm>0</soft_cfm>
                <soft_erp>0.2</soft_erp>
                <kp>100000</kp>
                <kd>1</kd>
              </bullet>
            </contact>
          </surface>
        </collision>
      </link>
      <link name='pic2::link'>
        <pose>0.1889 0 0.06832 0 1.20502 0</pose>
        <self_collide>0</self_collide>
        <enable_wind>0</enable_wind>
        <kinematic>0</kinematic>
        <gravity>1</gravity>
        <inertial>
          <mass>1e-06</mass>
          <pose>0 0 0 0 -0 0</pose>
          <inertia>
            <ixx>1e-09</ixx>
            <ixy>0</ixy>
            <ixz>0</ixz>
            <iyy>1e-09</iyy>
            <iyz>0</iyz>
            <izz>1e-09</izz>
          </inertia>
        </inertial>
        <visual name='visual'>
          <geometry>
            <mesh>
              <uri>model://pic2/meshes/pic2.dae</uri>
              <scale>0.16 0.16 0.16</scale>
            </mesh>
          </geometry>
          <pose>0 0 0 0 -0 0</pose>
          <transparency>0</transparency>
          <cast_shadows>1</cast_shadows>
          <material>
            <shader type='pixel'/>
          </material>
        </visual>
      </link>
      <joint name='aruco_joint' type='fixed'>
        <parent>body</parent>
        <child>pic2::link</child>
        <pose>0 0 0 0 -0 0</pose>
        <physics>
          <ode>
            <limit>
              <cfm>0</cfm>
              <erp>0.2</erp>
            </limit>
            <suspension>
              <cfm>0</cfm>
              <erp>0.2</erp>
            </suspension>
          </ode>
        </physics>
      </joint>
      <joint name='box_joint' type='fixed'>
        <parent>body</parent>
        <child>box_link</child>
        <pose>0 0 0 0 -0 0</pose>
        <physics>
          <ode>
            <limit>
              <cfm>0</cfm>
              <erp>0.2</erp>
            </limit>
            <suspension>
              <cfm>0</cfm>
              <erp>0.2</erp>
            </suspension>
          </ode>
        </physics>
      </joint>
      <static>0</static>
      <allow_auto_disable>1</allow_auto_disable>
      <pose>0.977735 0.492982 0 0 -0 0</pose>
    </model>
  </world>
</sdf>
