<?xml version="1.0" ?>
<sdf version='1.7'>
  <world name='default'>
    <gui fullscreen='0'>
      <camera name='user_camera'>
        <pose>-0.305621 1.68652 2.51099 0 0.854981 -0.64304</pose>
        <view_controller>orbit</view_controller>
        <projection_type>perspective</projection_type>
      </camera>
    </gui>
    <gravity>0 0 -9.81</gravity>
    <physics name='default_physics' default='0' type='ode'>
      <max_step_size>0.001</max_step_size>
      <real_time_factor>1</real_time_factor>
      <real_time_update_rate>1000</real_time_update_rate>
    </physics>
    <scene>
      <ambient>0.4 0.4 0.4 1</ambient>
      <background>0.7 0.7 0.7 1</background>
      <shadows>1</shadows>
    </scene>
    <light name='sun' type='directional'>
      <cast_shadows>1</cast_shadows>
      <pose>0 0 10 0 -0 0</pose>
      <diffuse>0.8 0.8 0.8 1</diffuse>
      <specular>0.2 0.2 0.2 1</specular>
      <attenuation>
        <range>1000</range>
        <constant>0.9</constant>
        <linear>0.01</linear>
        <quadratic>0.001</quadratic>
      </attenuation>
      <direction>-0.5 0.1 -0.9</direction>
      <spot>
        <inner_angle>0</inner_angle>
        <outer_angle>0</outer_angle>
        <falloff>0</falloff>
      </spot>
    </light>
    <model name='ground_plane'>
      <static>1</static>
      <link name='link'>
        <collision name='collision'>
          <geometry>
            <plane>
              <normal>0 0 1</normal>
              <size>100 100</size>
            </plane>
          </geometry>
          <surface>
            <contact>
              <collide_bitmask>65535</collide_bitmask>
              <ode/>
            </contact>
            <friction>
              <ode>
                <mu>100</mu>
                <mu2>50</mu2>
              </ode>
              <torsional>
                <ode/>
              </torsional>
            </friction>
            <bounce/>
          </surface>
          <max_contacts>10</max_contacts>
        </collision>
        <visual name='visual'>
          <cast_shadows>0</cast_shadows>
          <geometry>
            <plane>
              <normal>0 0 1</normal>
              <size>100 100</size>
            </plane>
          </geometry>
          <material>
            <script>
              <uri>file://media/materials/scripts/gazebo.material</uri>
              <name>Gazebo/Grey</name>
            </script>
          </material>
        </visual>
        <self_collide>0</self_collide>
        <enable_wind>0</enable_wind>
        <kinematic>0</kinematic>
      </link>
      <pose>0 0 0 0 -0 0</pose>
    </model>
    <model name='xarm_base'>
      <static>1</static>
      <link name='top_plate'>
        <pose>0 0 0.755 0 -0 0</pose>
        <collision name='top_plate_collision'>
          <geometry>
            <box>
              <size>0.25 0.25 0.04</size>
            </box>
          </geometry>
          <surface>
            <contact>
              <collide_bitmask>1</collide_bitmask>
              <ode/>
            </contact>
            <bounce/>
            <friction>
              <torsional>
                <ode/>
              </torsional>
              <ode/>
            </friction>
          </surface>
          <max_contacts>10</max_contacts>
        </collision>
        <visual name='top_plate_visual'>
          <geometry>
            <box>
              <size>0.25 0.25 0.04</size>
            </box>
          </geometry>
          <material>
            <script>
              <uri>file://media/materials/scripts/gazebo.material</uri>
              <name>Gazebo/Grey</name>
            </script>
          </material>
        </visual>
        <self_collide>0</self_collide>
        <enable_wind>0</enable_wind>
        <kinematic>0</kinematic>
      </link>
      <link name='leg1'>
        <pose>0.1 0.1 0.285 0 -0 0</pose>
        <collision name='leg1_collision'>
          <geometry>
            <box>
              <size>0.04 0.04 0.965</size>
            </box>
          </geometry>
          <max_contacts>10</max_contacts>
          <surface>
            <contact>
              <ode/>
            </contact>
            <bounce/>
            <friction>
              <torsional>
                <ode/>
              </torsional>
              <ode/>
            </friction>
          </surface>
        </collision>
        <visual name='leg1_visual'>
          <geometry>
            <box>
              <size>0.04 0.04 0.965</size>
            </box>
          </geometry>
          <material>
            <script>
              <uri>file://media/materials/scripts/gazebo.material</uri>
              <name>Gazebo/Grey</name>
            </script>
          </material>
        </visual>
        <self_collide>0</self_collide>
        <enable_wind>0</enable_wind>
        <kinematic>0</kinematic>
      </link>
      <link name='leg2'>
        <pose>-0.1 0.1 0.285 0 -0 0</pose>
        <collision name='leg2_collision'>
          <geometry>
            <box>
              <size>0.04 0.04 0.965</size>
            </box>
          </geometry>
          <max_contacts>10</max_contacts>
          <surface>
            <contact>
              <ode/>
            </contact>
            <bounce/>
            <friction>
              <torsional>
                <ode/>
              </torsional>
              <ode/>
            </friction>
          </surface>
        </collision>
        <visual name='leg2_visual'>
          <geometry>
            <box>
              <size>0.04 0.04 0.965</size>
            </box>
          </geometry>
          <material>
            <script>
              <uri>file://media/materials/scripts/gazebo.material</uri>
              <name>Gazebo/Grey</name>
            </script>
          </material>
        </visual>
        <self_collide>0</self_collide>
        <enable_wind>0</enable_wind>
        <kinematic>0</kinematic>
      </link>
      <link name='leg3'>
        <pose>0.1 -0.1 0.285 0 -0 0</pose>
        <collision name='leg3_collision'>
          <geometry>
            <box>
              <size>0.04 0.04 0.965</size>
            </box>
          </geometry>
          <max_contacts>10</max_contacts>
          <surface>
            <contact>
              <ode/>
            </contact>
            <bounce/>
            <friction>
              <torsional>
                <ode/>
              </torsional>
              <ode/>
            </friction>
          </surface>
        </collision>
        <visual name='leg3_visual'>
          <geometry>
            <box>
              <size>0.04 0.04 0.965</size>
            </box>
          </geometry>
          <material>
            <script>
              <uri>file://media/materials/scripts/gazebo.material</uri>
              <name>Gazebo/Grey</name>
            </script>
          </material>
        </visual>
        <self_collide>0</self_collide>
        <enable_wind>0</enable_wind>
        <kinematic>0</kinematic>
      </link>
      <link name='leg4'>
        <pose>-0.1 -0.1 0.285 0 -0 0</pose>
        <collision name='leg4_collision'>
          <geometry>
            <box>
              <size>0.04 0.04 0.965</size>
            </box>
          </geometry>
          <max_contacts>10</max_contacts>
          <surface>
            <contact>
              <ode/>
            </contact>
            <bounce/>
            <friction>
              <torsional>
                <ode/>
              </torsional>
              <ode/>
            </friction>
          </surface>
        </collision>
        <visual name='leg4_visual'>
          <geometry>
            <box>
              <size>0.04 0.04 0.965</size>
            </box>
          </geometry>
          <material>
            <script>
              <uri>file://media/materials/scripts/gazebo.material</uri>
              <name>Gazebo/Grey</name>
            </script>
          </material>
        </visual>
        <self_collide>0</self_collide>
        <enable_wind>0</enable_wind>
        <kinematic>0</kinematic>
      </link>
    </model>
    <model name='cafe_table'>
      <static>1</static>
      <frame name='cafe_table::__model__' attached_to='cafe_table::link'>
        <pose relative_to='__model__'>0.7 0 0 0 -0 0</pose>
      </frame>
      <static>1</static>
      <link name='cafe_table::link'>
        <collision name='surface'>
          <pose>0 0 0.755 0 -0 0</pose>
          <geometry>
            <box>
              <size>0.913 0.913 0.04</size>
            </box>
          </geometry>
          <max_contacts>10</max_contacts>
          <surface>
            <contact>
              <ode/>
            </contact>
            <bounce/>
            <friction>
              <torsional>
                <ode/>
              </torsional>
              <ode/>
            </friction>
          </surface>
        </collision>
        <collision name='column'>
          <pose>0 0 0.37 0 -0 0</pose>
          <geometry>
            <box>
              <size>0.042 0.042 0.74</size>
            </box>
          </geometry>
          <max_contacts>10</max_contacts>
          <surface>
            <contact>
              <ode/>
            </contact>
            <bounce/>
            <friction>
              <torsional>
                <ode/>
              </torsional>
              <ode/>
            </friction>
          </surface>
        </collision>
        <collision name='base'>
          <pose>0 0 0.02 0 -0 0</pose>
          <geometry>
            <box>
              <size>0.56 0.56 0.04</size>
            </box>
          </geometry>
          <max_contacts>10</max_contacts>
          <surface>
            <contact>
              <ode/>
            </contact>
            <bounce/>
            <friction>
              <torsional>
                <ode/>
              </torsional>
              <ode/>
            </friction>
          </surface>
        </collision>
        <visual name='visual'>
          <geometry>
            <mesh>
              <uri>model://cafe_table/meshes/cafe_table.dae</uri>
            </mesh>
          </geometry>
        </visual>
        <pose relative_to='cafe_table::__model__'>0 0 0 0 -0 0</pose>
        <self_collide>0</self_collide>
        <enable_wind>0</enable_wind>
        <kinematic>0</kinematic>
      </link>
    </model>
    <magnetic_field>6e-06 2.3e-05 -4.2e-05</magnetic_field>
    <atmosphere type='adiabatic'/>
    <wind/>
    <spherical_coordinates>
      <surface_model>EARTH_WGS84</surface_model>
      <latitude_deg>0</latitude_deg>
      <longitude_deg>0</longitude_deg>
      <elevation>0</elevation>
      <heading_deg>0</heading_deg>
    </spherical_coordinates>
    <model name='xarm6'>
      <joint name='world_joint' type='fixed'>
        <pose relative_to='__model__'>0 0 0 0 -0 0</pose>
        <parent>world</parent>
        <child>link_base</child>
      </joint>
      <link name='link_base'>
        <pose relative_to='world_joint'>0 0 0 0 -0 0</pose>
        <inertial>
          <pose>0.047724 0.006966 0.165442 0 -0 0</pose>
          <mass>2.9</mass>
          <inertia>
            <ixx>0.245626</ixx>
            <ixy>-0.0130179</ixy>
            <ixz>-0.139018</ixz>
            <iyy>0.330887</iyy>
            <iyz>-0.0202904</iyz>
            <izz>0.115286</izz>
          </inertia>
        </inertial>
        <collision name='link_base_collision'>
          <pose>0 0 0 0 -0 0</pose>
          <geometry>
            <mesh>
              <scale>1 1 1</scale>
              <uri>/home/snehith/catkin_ws/src/xarm_ros_mod/xarm_description/meshes/xarm6/visual/base.stl</uri>
            </mesh>
          </geometry>
          <surface>
            <contact>
              <ode/>
            </contact>
            <friction>
              <ode/>
              <torsional>
                <ode/>
              </torsional>
            </friction>
            <bounce/>
          </surface>
          <max_contacts>10</max_contacts>
        </collision>
        <collision name='link_base_fixed_joint_lump__link_camera_collision_1'>
          <pose>0.692 0.001 1.17 3.14159 1.57079 3.14159</pose>
          <geometry>
            <sphere>
              <radius>0.02</radius>
            </sphere>
          </geometry>
          <surface>
            <contact>
              <ode/>
            </contact>
            <friction>
              <ode/>
              <torsional>
                <ode/>
              </torsional>
            </friction>
            <bounce/>
          </surface>
          <max_contacts>10</max_contacts>
        </collision>
        <collision name='link_base_fixed_joint_lump__new_camera_link_collision_2'>
          <pose>0.692 0.201 1.17 3.14159 1.57079 3.14159</pose>
          <geometry>
            <sphere>
              <radius>0.02</radius>
            </sphere>
          </geometry>
          <surface>
            <contact>
              <ode/>
            </contact>
            <friction>
              <ode/>
              <torsional>
                <ode/>
              </torsional>
            </friction>
            <bounce/>
          </surface>
          <max_contacts>10</max_contacts>
        </collision>
        <visual name='link_base_visual'>
          <pose>0 0 0 0 -0 0</pose>
          <geometry>
            <mesh>
              <scale>1 1 1</scale>
              <uri>/home/snehith/catkin_ws/src/xarm_ros_mod/xarm_description/meshes/xarm6/visual/base.stl</uri>
            </mesh>
          </geometry>
        </visual>
        <visual name='link_base_fixed_joint_lump__link_camera_visual_1'>
          <pose>0.692 0.001 1.17 3.14159 1.57079 3.14159</pose>
          <geometry>
            <sphere>
              <radius>0.02</radius>
            </sphere>
          </geometry>
          <material>
            <script>
              <name>Gazebo/Black</name>
              <uri>file://media/materials/scripts/gazebo.material</uri>
            </script>
          </material>
        </visual>
        <visual name='link_base_fixed_joint_lump__new_camera_link_visual_2'>
          <pose>0.692 0.201 1.17 3.14159 1.57079 3.14159</pose>
          <geometry>
            <sphere>
              <radius>0.02</radius>
            </sphere>
          </geometry>
        </visual>
        <self_collide>1</self_collide>
        <sensor name='xarm_camera_node' type='camera'>
          <update_rate>10</update_rate>
          <camera name='head'>
            <horizontal_fov>0.994838</horizontal_fov>
            <image>
              <width>1920</width>
              <height>1080</height>
              <format>B8G8R8</format>
            </image>
            <clip>
              <near>0.02</near>
              <far>300</far>
            </clip>
            <noise>
              <type>gaussian</type>
              <mean>0</mean>
              <stddev>0.007</stddev>
            </noise>
            <lens>
              <intrinsics>
                <fx>1493</fx>
                <fy>1493</fy>
                <cx>960</cx>
                <cy>540</cy>
                <s>0</s>
              </intrinsics>
              <type>stereographic</type>
              <scale_to_hfov>1</scale_to_hfov>
            </lens>
          </camera>
          <plugin name='gazebo_camera' filename='libgazebo_ros_camera.so'>
            <alwaysOn>1</alwaysOn>
            <updateRate>0.0</updateRate>
            <cameraName>/camera</cameraName>
            <imageTopicName>image_raw</imageTopicName>
            <cameraInfoTopicName>camera_info</cameraInfoTopicName>
            <frameName>camera_link</frameName>
            <hackBaseline>0.07</hackBaseline>
            <distortionK1>0.0</distortionK1>
            <distortionK2>0.0</distortionK2>
            <distortionK3>0.0</distortionK3>
            <distortionT1>0.0</distortionT1>
            <distortionT2>0.0</distortionT2>
            <robotNamespace>/</robotNamespace>
          </plugin>
          <pose>0.692 0.001 1.17 3.14159 1.57079 3.14159</pose>
        </sensor>
        <sensor name='camera2' type='camera'>
          <update_rate>10</update_rate>
          <camera name='head'>
            <horizontal_fov>0.994838</horizontal_fov>
            <image>
              <width>1920</width>
              <height>1080</height>
              <format>B8G8R8</format>
            </image>
            <clip>
              <near>0.02</near>
              <far>300</far>
            </clip>
            <noise>
              <type>gaussian</type>
              <mean>0</mean>
              <stddev>0.007</stddev>
            </noise>
            <lens>
              <intrinsics>
                <fx>1493</fx>
                <fy>1493</fy>
                <cx>960</cx>
                <cy>540</cy>
                <s>0</s>
              </intrinsics>
              <type>stereographic</type>
              <scale_to_hfov>1</scale_to_hfov>
            </lens>
          </camera>
          <plugin name='gazebo_camera' filename='libgazebo_ros_camera.so'>
            <alwaysOn>1</alwaysOn>
            <updateRate>0.0</updateRate>
            <cameraName>/camera2</cameraName>
            <imageTopicName>image_raw</imageTopicName>
            <cameraInfoTopicName>camera_info</cameraInfoTopicName>
            <frameName>new_camera_link</frameName>
            <hackBaseline>0.07</hackBaseline>
            <distortionK1>0.0</distortionK1>
            <distortionK2>0.0</distortionK2>
            <distortionK3>0.0</distortionK3>
            <distortionT1>0.0</distortionT1>
            <distortionT2>0.0</distortionT2>
            <robotNamespace>/</robotNamespace>
          </plugin>
          <pose>0.692 0.201 1.17 3.14159 1.57079 3.14159</pose>
        </sensor>
        <enable_wind>0</enable_wind>
        <kinematic>0</kinematic>
      </link>
      <joint name='joint1' type='revolute'>
        <pose relative_to='link_base'>0 0 0.267 0 -0 0</pose>
        <parent>link_base</parent>
        <child>link1</child>
        <axis>
          <xyz>0 0 1</xyz>
          <limit>
            <lower>-3.11018</lower>
            <upper>3.11018</upper>
            <effort>50</effort>
            <velocity>3.14</velocity>
          </limit>
          <dynamics>
            <damping>1</damping>
            <friction>1</friction>
            <spring_reference>0</spring_reference>
            <spring_stiffness>0</spring_stiffness>
          </dynamics>
        </axis>
      </joint>
      <link name='link1'>
        <pose relative_to='joint1'>0 0 0 0 -0 0</pose>
        <inertial>
          <pose>-0.002 0.02692 -0.01332 0 -0 0</pose>
          <mass>2.16</mass>
          <inertia>
            <ixx>0.00539427</ixx>
            <ixy>1.095e-05</ixy>
            <ixz>1.635e-06</ixz>
            <iyy>0.0048979</iyy>
            <iyz>0.000793</iyz>
            <izz>0.00311573</izz>
          </inertia>
        </inertial>
        <collision name='link1_collision'>
          <pose>0 0 0 0 -0 0</pose>
          <geometry>
            <mesh>
              <scale>1 1 1</scale>
              <uri>/home/snehith/catkin_ws/src/xarm_ros_mod/xarm_description/meshes/xarm6/visual/link1.stl</uri>
            </mesh>
          </geometry>
          <surface>
            <contact>
              <ode/>
            </contact>
            <friction>
              <ode/>
              <torsional>
                <ode/>
              </torsional>
            </friction>
            <bounce/>
          </surface>
          <max_contacts>10</max_contacts>
        </collision>
        <visual name='link1_visual'>
          <pose>0 0 0 0 -0 0</pose>
          <geometry>
            <mesh>
              <scale>1 1 1</scale>
              <uri>/home/snehith/catkin_ws/src/xarm_ros_mod/xarm_description/meshes/xarm6/visual/link1.stl</uri>
            </mesh>
          </geometry>
        </visual>
        <self_collide>1</self_collide>
        <enable_wind>0</enable_wind>
        <kinematic>0</kinematic>
      </link>
      <joint name='joint2' type='revolute'>
        <pose relative_to='link1'>0 0 0 -1.5708 0 0</pose>
        <parent>link1</parent>
        <child>link2</child>
        <axis>
          <xyz>0 0 1</xyz>
          <limit>
            <lower>-2.059</lower>
            <upper>2.0944</upper>
            <effort>50</effort>
            <velocity>3.14</velocity>
          </limit>
          <dynamics>
            <damping>1</damping>
            <friction>1</friction>
            <spring_reference>0</spring_reference>
            <spring_stiffness>0</spring_stiffness>
          </dynamics>
        </axis>
      </joint>
      <link name='link2'>
        <pose relative_to='joint2'>0 0 0 0 -0 0</pose>
        <inertial>
          <pose>0.03531 -0.21398 0.03386 0 -0 0</pose>
          <mass>1.71</mass>
          <inertia>
            <ixx>0.0248674</ixx>
            <ixy>-0.00430651</ixy>
            <ixz>-0.00067797</ixz>
            <iyy>0.00485548</iyy>
            <iyz>0.00457245</iyz>
            <izz>0.0238783</izz>
          </inertia>
        </inertial>
        <collision name='link2_collision'>
          <pose>0 0 0 0 -0 0</pose>
          <geometry>
            <mesh>
              <scale>1 1 1</scale>
              <uri>/home/snehith/catkin_ws/src/xarm_ros_mod/xarm_description/meshes/xarm6/visual/link2.stl</uri>
            </mesh>
          </geometry>
          <surface>
            <contact>
              <ode/>
            </contact>
            <friction>
              <ode/>
              <torsional>
                <ode/>
              </torsional>
            </friction>
            <bounce/>
          </surface>
          <max_contacts>10</max_contacts>
        </collision>
        <visual name='link2_visual'>
          <pose>0 0 0 0 -0 0</pose>
          <geometry>
            <mesh>
              <scale>1 1 1</scale>
              <uri>/home/snehith/catkin_ws/src/xarm_ros_mod/xarm_description/meshes/xarm6/visual/link2.stl</uri>
            </mesh>
          </geometry>
        </visual>
        <self_collide>1</self_collide>
        <enable_wind>0</enable_wind>
        <kinematic>0</kinematic>
      </link>
      <joint name='joint3' type='revolute'>
        <pose relative_to='link2'>0.0535 -0.2845 0 0 -0 0</pose>
        <parent>link2</parent>
        <child>link3</child>
        <axis>
          <xyz>0 0 1</xyz>
          <limit>
            <lower>-3.11018</lower>
            <upper>0.19198</upper>
            <effort>32</effort>
            <velocity>3.14</velocity>
          </limit>
          <dynamics>
            <damping>1</damping>
            <friction>1</friction>
            <spring_reference>0</spring_reference>
            <spring_stiffness>0</spring_stiffness>
          </dynamics>
        </axis>
      </joint>
      <link name='link3'>
        <pose relative_to='joint3'>0 0 0 0 -0 0</pose>
        <inertial>
          <pose>0.06781 0.10749 0.01457 0 -0 0</pose>
          <mass>1.384</mass>
          <inertia>
            <ixx>0.0053694</ixx>
            <ixy>0.0014185</ixy>
            <ixz>-0.00092094</ixz>
            <iyy>0.0032423</iyy>
            <iyz>-0.00169178</iyz>
            <izz>0.00501731</izz>
          </inertia>
        </inertial>
        <collision name='link3_collision'>
          <pose>0 0 0 0 -0 0</pose>
          <geometry>
            <mesh>
              <scale>1 1 1</scale>
              <uri>/home/snehith/catkin_ws/src/xarm_ros_mod/xarm_description/meshes/xarm6/visual/link3.stl</uri>
            </mesh>
          </geometry>
          <surface>
            <contact>
              <ode/>
            </contact>
            <friction>
              <ode/>
              <torsional>
                <ode/>
              </torsional>
            </friction>
            <bounce/>
          </surface>
          <max_contacts>10</max_contacts>
        </collision>
        <visual name='link3_visual'>
          <pose>0 0 0 0 -0 0</pose>
          <geometry>
            <mesh>
              <scale>1 1 1</scale>
              <uri>/home/snehith/catkin_ws/src/xarm_ros_mod/xarm_description/meshes/xarm6/visual/link3.stl</uri>
            </mesh>
          </geometry>
        </visual>
        <self_collide>1</self_collide>
        <enable_wind>0</enable_wind>
        <kinematic>0</kinematic>
      </link>
      <joint name='joint4' type='revolute'>
        <pose relative_to='link3'>0.0775 0.3425 0 -1.5708 0 0</pose>
        <parent>link3</parent>
        <child>link4</child>
        <axis>
          <xyz>0 0 1</xyz>
          <limit>
            <lower>-3.11018</lower>
            <upper>3.11018</upper>
            <effort>32</effort>
            <velocity>3.14</velocity>
          </limit>
          <dynamics>
            <damping>1</damping>
            <friction>1</friction>
            <spring_reference>0</spring_reference>
            <spring_stiffness>0</spring_stiffness>
          </dynamics>
        </axis>
      </joint>
      <link name='link4'>
        <pose relative_to='joint4'>0 0 0 0 -0 0</pose>
        <inertial>
          <pose>-0.00021 0.02578 -0.02538 0 -0 0</pose>
          <mass>1.115</mass>
          <inertia>
            <ixx>0.00439263</ixx>
            <ixy>5.028e-05</ixy>
            <ixz>1.374e-05</ixz>
            <iyy>0.0040077</iyy>
            <iyz>0.00045338</iyz>
            <izz>0.00110321</izz>
          </inertia>
        </inertial>
        <collision name='link4_collision'>
          <pose>0 0 0 0 -0 0</pose>
          <geometry>
            <mesh>
              <scale>1 1 1</scale>
              <uri>/home/snehith/catkin_ws/src/xarm_ros_mod/xarm_description/meshes/xarm6/visual/link4.stl</uri>
            </mesh>
          </geometry>
          <surface>
            <contact>
              <ode/>
            </contact>
            <friction>
              <ode/>
              <torsional>
                <ode/>
              </torsional>
            </friction>
            <bounce/>
          </surface>
          <max_contacts>10</max_contacts>
        </collision>
        <visual name='link4_visual'>
          <pose>0 0 0 0 -0 0</pose>
          <geometry>
            <mesh>
              <scale>1 1 1</scale>
              <uri>/home/snehith/catkin_ws/src/xarm_ros_mod/xarm_description/meshes/xarm6/visual/link4.stl</uri>
            </mesh>
          </geometry>
        </visual>
        <self_collide>1</self_collide>
        <enable_wind>0</enable_wind>
        <kinematic>0</kinematic>
      </link>
      <joint name='joint5' type='revolute'>
        <pose relative_to='link4'>0 0 0 1.5708 -0 0</pose>
        <parent>link4</parent>
        <child>link5</child>
        <axis>
          <xyz>0 0 1</xyz>
          <limit>
            <lower>-1.69297</lower>
            <upper>3.11018</upper>
            <effort>32</effort>
            <velocity>3.14</velocity>
          </limit>
          <dynamics>
            <damping>1</damping>
            <friction>1</friction>
            <spring_reference>0</spring_reference>
            <spring_stiffness>0</spring_stiffness>
          </dynamics>
        </axis>
      </joint>
      <link name='link5'>
        <pose relative_to='joint5'>0 0 0 0 -0 0</pose>
        <inertial>
          <pose>0.05428 0.01781 0.00543 0 -0 0</pose>
          <mass>1.275</mass>
          <inertia>
            <ixx>0.00120276</ixx>
            <ixy>0.000492428</ixy>
            <ixz>-0.00039147</ixz>
            <iyy>0.0022876</iyy>
            <iyz>-0.0001235</iyz>
            <izz>0.0026866</izz>
          </inertia>
        </inertial>
        <collision name='link5_collision'>
          <pose>0 0 0 0 -0 0</pose>
          <geometry>
            <mesh>
              <scale>1 1 1</scale>
              <uri>/home/snehith/catkin_ws/src/xarm_ros_mod/xarm_description/meshes/xarm6/visual/link5.stl</uri>
            </mesh>
          </geometry>
          <surface>
            <contact>
              <ode/>
            </contact>
            <friction>
              <ode/>
              <torsional>
                <ode/>
              </torsional>
            </friction>
            <bounce/>
          </surface>
          <max_contacts>10</max_contacts>
        </collision>
        <visual name='link5_visual'>
          <pose>0 0 0 0 -0 0</pose>
          <geometry>
            <mesh>
              <scale>1 1 1</scale>
              <uri>/home/snehith/catkin_ws/src/xarm_ros_mod/xarm_description/meshes/xarm6/visual/link5.stl</uri>
            </mesh>
          </geometry>
        </visual>
        <self_collide>1</self_collide>
        <enable_wind>0</enable_wind>
        <kinematic>0</kinematic>
      </link>
      <joint name='joint6' type='revolute'>
        <pose relative_to='link5'>0.076 0.097 0 -1.5708 0 0</pose>
        <parent>link5</parent>
        <child>link6</child>
        <axis>
          <xyz>0 0 1</xyz>
          <limit>
            <lower>-3.11018</lower>
            <upper>3.11018</upper>
            <effort>20</effort>
            <velocity>3.14</velocity>
          </limit>
          <dynamics>
            <damping>1</damping>
            <friction>1</friction>
            <spring_reference>0</spring_reference>
            <spring_stiffness>0</spring_stiffness>
          </dynamics>
        </axis>
      </joint>
      <link name='link6'>
        <pose relative_to='joint6'>0 0 0 0 -0 0</pose>
        <inertial>
          <pose>-0.000545 -0.001431 0.038342 0 -0 0</pose>
          <mass>0.65116</mass>
          <inertia>
            <ixx>0.000818795</ixx>
            <ixy>2.44297e-07</ixy>
            <ixz>6.08903e-06</ixz>
            <iyy>0.000680747</iyy>
            <iyz>2.08511e-06</iyz>
            <izz>0.000336739</izz>
          </inertia>
        </inertial>
        <collision name='link6_collision'>
          <pose>0 0 0 0 -0 0</pose>
          <geometry>
            <mesh>
              <scale>1 1 1</scale>
              <uri>/home/snehith/catkin_ws/src/xarm_ros_mod/xarm_description/meshes/collision/end_tool.STL</uri>
            </mesh>
          </geometry>
          <surface>
            <contact>
              <ode/>
            </contact>
            <friction>
              <ode/>
              <torsional>
                <ode/>
              </torsional>
            </friction>
            <bounce/>
          </surface>
          <max_contacts>10</max_contacts>
        </collision>
        <collision name='link6_fixed_joint_lump__xarm_gripper_base_link_collision_1'>
          <pose>0 0 0 0 -0 0</pose>
          <geometry>
            <mesh>
              <scale>1 1 1</scale>
              <uri>/home/snehith/catkin_ws/src/xarm_ros_mod/xarm_gripper/meshes/base_link_collision.STL</uri>
            </mesh>
          </geometry>
          <surface>
            <contact>
              <ode/>
            </contact>
            <friction>
              <ode/>
              <torsional>
                <ode/>
              </torsional>
            </friction>
            <bounce/>
          </surface>
          <max_contacts>10</max_contacts>
        </collision>
        <visual name='link6_visual'>
          <pose>0 0 0 0 -0 0</pose>
          <geometry>
            <mesh>
              <scale>1 1 1</scale>
              <uri>/home/snehith/catkin_ws/src/xarm_ros_mod/xarm_description/meshes/xarm6/visual/link6.stl</uri>
            </mesh>
          </geometry>
        </visual>
        <visual name='link6_fixed_joint_lump__xarm_gripper_base_link_visual_1'>
          <pose>0 0 0 0 -0 0</pose>
          <geometry>
            <mesh>
              <scale>1 1 1</scale>
              <uri>/home/snehith/catkin_ws/src/xarm_ros_mod/xarm_gripper/meshes/base_link.STL</uri>
            </mesh>
          </geometry>
        </visual>
        <self_collide>0</self_collide>
        <enable_wind>0</enable_wind>
        <kinematic>0</kinematic>
      </link>
      <joint name='drive_joint' type='revolute'>
        <pose relative_to='link6'>0 0.035 0.059098 0 -0 0</pose>
        <parent>link6</parent>
        <child>left_outer_knuckle</child>
        <axis>
          <xyz>1 0 0</xyz>
          <limit>
            <lower>0</lower>
            <upper>0.85</upper>
            <effort>50</effort>
            <velocity>2</velocity>
          </limit>
          <dynamics>
            <spring_reference>0</spring_reference>
            <spring_stiffness>0</spring_stiffness>
          </dynamics>
        </axis>
      </joint>
      <link name='left_outer_knuckle'>
        <pose relative_to='drive_joint'>0 0 0 0 -0 0</pose>
        <inertial>
          <pose>0 0.021559 0.015181 0 -0 0</pose>
          <mass>0.033618</mass>
          <inertia>
            <ixx>1.9111e-05</ixx>
            <ixy>-1.8803e-17</ixy>
            <ixz>-1.1002e-17</ixz>
            <iyy>6.6256e-06</iyy>
            <iyz>-7.3008e-06</iyz>
            <izz>1.3185e-05</izz>
          </inertia>
        </inertial>
        <collision name='left_outer_knuckle_collision'>
          <pose>0 0 0 0 -0 0</pose>
          <geometry>
            <mesh>
              <scale>1 1 1</scale>
              <uri>/home/snehith/catkin_ws/src/xarm_ros_mod/xarm_gripper/meshes/left_outer_knuckle.STL</uri>
            </mesh>
          </geometry>
          <surface>
            <contact>
              <ode/>
            </contact>
            <friction>
              <ode/>
              <torsional>
                <ode/>
              </torsional>
            </friction>
            <bounce/>
          </surface>
          <max_contacts>10</max_contacts>
        </collision>
        <visual name='left_outer_knuckle_visual'>
          <pose>0 0 0 0 -0 0</pose>
          <geometry>
            <mesh>
              <scale>1 1 1</scale>
              <uri>/home/snehith/catkin_ws/src/xarm_ros_mod/xarm_gripper/meshes/left_outer_knuckle.STL</uri>
            </mesh>
          </geometry>
        </visual>
        <self_collide>0</self_collide>
        <enable_wind>0</enable_wind>
        <kinematic>0</kinematic>
      </link>
      <joint name='left_finger_joint' type='revolute'>
        <pose relative_to='left_outer_knuckle'>0 0.035465 0.042039 0 -0 0</pose>
        <parent>left_outer_knuckle</parent>
        <child>left_finger</child>
        <axis>
          <xyz>-1 0 0</xyz>
          <limit>
            <lower>0</lower>
            <upper>0.85</upper>
            <effort>50</effort>
            <velocity>2</velocity>
          </limit>
          <dynamics>
            <spring_reference>0</spring_reference>
            <spring_stiffness>0</spring_stiffness>
          </dynamics>
        </axis>
      </joint>
      <link name='left_finger'>
        <pose relative_to='left_finger_joint'>0 0 0 0 -0 0</pose>
        <inertial>
          <pose>-0 -0.016413 0.029258 0 -0 0</pose>
          <mass>0.048304</mass>
          <inertia>
            <ixx>1.7493e-05</ixx>
            <ixy>-4.2156e-19</ixy>
            <ixz>6.9164e-18</ixz>
            <iyy>1.7225e-05</iyy>
            <iyz>4.6433e-06</iyz>
            <izz>5.1466e-06</izz>
          </inertia>
        </inertial>
        <collision name='left_finger_collision'>
          <pose>0 0 0 0 -0 0</pose>
          <geometry>
            <mesh>
              <scale>1 1 1</scale>
              <uri>/home/snehith/catkin_ws/src/xarm_ros_mod/xarm_gripper/meshes/left_finger.STL</uri>
            </mesh>
          </geometry>
          <surface>
            <contact>
              <ode/>
            </contact>
            <friction>
              <ode/>
              <torsional>
                <ode/>
              </torsional>
            </friction>
            <bounce/>
          </surface>
          <max_contacts>10</max_contacts>
        </collision>
        <visual name='left_finger_visual'>
          <pose>0 0 0 0 -0 0</pose>
          <geometry>
            <mesh>
              <scale>1 1 1</scale>
              <uri>/home/snehith/catkin_ws/src/xarm_ros_mod/xarm_gripper/meshes/left_finger.STL</uri>
            </mesh>
          </geometry>
        </visual>
        <self_collide>0</self_collide>
        <enable_wind>0</enable_wind>
        <kinematic>0</kinematic>
      </link>
      <joint name='left_inner_knuckle_joint' type='revolute'>
        <pose relative_to='link6'>0 0.02 0.074098 0 -0 0</pose>
        <parent>link6</parent>
        <child>left_inner_knuckle</child>
        <axis>
          <xyz>1 0 0</xyz>
          <limit>
            <lower>0</lower>
            <upper>0.85</upper>
            <effort>50</effort>
            <velocity>2</velocity>
          </limit>
          <dynamics>
            <spring_reference>0</spring_reference>
            <spring_stiffness>0</spring_stiffness>
          </dynamics>
        </axis>
      </joint>
      <link name='left_inner_knuckle'>
        <pose relative_to='left_inner_knuckle_joint'>0 0 0 0 -0 0</pose>
        <inertial>
          <pose>2e-06 0.022047 0.026133 0 -0 0</pose>
          <mass>0.0230126</mass>
          <inertia>
            <ixx>6.0949e-06</ixx>
            <ixy>6.06651e-11</ixy>
            <ixz>7.19103e-11</ixz>
            <iyy>6.01955e-06</iyy>
            <iyz>-2.75317e-06</iyz>
            <izz>5.07862e-06</izz>
          </inertia>
        </inertial>
        <collision name='left_inner_knuckle_collision'>
          <pose>0 0 0 0 -0 0</pose>
          <geometry>
            <mesh>
              <scale>1 1 1</scale>
              <uri>/home/snehith/catkin_ws/src/xarm_ros_mod/xarm_gripper/meshes/left_inner_knuckle.STL</uri>
            </mesh>
          </geometry>
          <surface>
            <contact>
              <ode/>
            </contact>
            <friction>
              <ode/>
              <torsional>
                <ode/>
              </torsional>
            </friction>
            <bounce/>
          </surface>
          <max_contacts>10</max_contacts>
        </collision>
        <visual name='left_inner_knuckle_visual'>
          <pose>0 0 0 0 -0 0</pose>
          <geometry>
            <mesh>
              <scale>1 1 1</scale>
              <uri>/home/snehith/catkin_ws/src/xarm_ros_mod/xarm_gripper/meshes/left_inner_knuckle.STL</uri>
            </mesh>
          </geometry>
        </visual>
        <self_collide>0</self_collide>
        <enable_wind>0</enable_wind>
        <kinematic>0</kinematic>
      </link>
      <joint name='right_inner_knuckle_joint' type='revolute'>
        <pose relative_to='link6'>0 -0.02 0.074098 0 -0 0</pose>
        <parent>link6</parent>
        <child>right_inner_knuckle</child>
        <axis>
          <xyz>-1 0 0</xyz>
          <limit>
            <lower>0</lower>
            <upper>0.85</upper>
            <effort>50</effort>
            <velocity>2</velocity>
          </limit>
          <dynamics>
            <spring_reference>0</spring_reference>
            <spring_stiffness>0</spring_stiffness>
          </dynamics>
        </axis>
      </joint>
      <link name='right_inner_knuckle'>
        <pose relative_to='right_inner_knuckle_joint'>0 0 0 0 -0 0</pose>
        <inertial>
          <pose>2e-06 -0.022047 0.026133 0 -0 0</pose>
          <mass>0.023013</mass>
          <inertia>
            <ixx>6.0949e-06</ixx>
            <ixy>-6.0665e-11</ixy>
            <ixz>7.191e-11</ixz>
            <iyy>6.0197e-06</iyy>
            <iyz>2.7531e-06</iyz>
            <izz>5.0784e-06</izz>
          </inertia>
        </inertial>
        <collision name='right_inner_knuckle_collision'>
          <pose>0 0 0 0 -0 0</pose>
          <geometry>
            <mesh>
              <scale>1 1 1</scale>
              <uri>/home/snehith/catkin_ws/src/xarm_ros_mod/xarm_gripper/meshes/right_inner_knuckle.STL</uri>
            </mesh>
          </geometry>
          <surface>
            <contact>
              <ode/>
            </contact>
            <friction>
              <ode/>
              <torsional>
                <ode/>
              </torsional>
            </friction>
            <bounce/>
          </surface>
          <max_contacts>10</max_contacts>
        </collision>
        <visual name='right_inner_knuckle_visual'>
          <pose>0 0 0 0 -0 0</pose>
          <geometry>
            <mesh>
              <scale>1 1 1</scale>
              <uri>/home/snehith/catkin_ws/src/xarm_ros_mod/xarm_gripper/meshes/right_inner_knuckle.STL</uri>
            </mesh>
          </geometry>
        </visual>
        <self_collide>0</self_collide>
        <enable_wind>0</enable_wind>
        <kinematic>0</kinematic>
      </link>
      <joint name='right_outer_knuckle_joint' type='revolute'>
        <pose relative_to='link6'>0 -0.035 0.059098 0 -0 0</pose>
        <parent>link6</parent>
        <child>right_outer_knuckle</child>
        <axis>
          <xyz>-1 0 0</xyz>
          <limit>
            <lower>0</lower>
            <upper>0.85</upper>
            <effort>50</effort>
            <velocity>2</velocity>
          </limit>
          <dynamics>
            <spring_reference>0</spring_reference>
            <spring_stiffness>0</spring_stiffness>
          </dynamics>
        </axis>
      </joint>
      <link name='right_outer_knuckle'>
        <pose relative_to='right_outer_knuckle_joint'>0 0 0 0 -0 0</pose>
        <inertial>
          <pose>-0 -0.021559 0.015181 0 -0 0</pose>
          <mass>0.033618</mass>
          <inertia>
            <ixx>1.9111e-05</ixx>
            <ixy>-1.8789e-17</ixy>
            <ixz>1.0986e-17</ixz>
            <iyy>6.6256e-06</iyy>
            <iyz>7.3008e-06</iyz>
            <izz>1.3185e-05</izz>
          </inertia>
        </inertial>
        <collision name='right_outer_knuckle_collision'>
          <pose>0 0 0 0 -0 0</pose>
          <geometry>
            <mesh>
              <scale>1 1 1</scale>
              <uri>/home/snehith/catkin_ws/src/xarm_ros_mod/xarm_gripper/meshes/right_outer_knuckle.STL</uri>
            </mesh>
          </geometry>
          <surface>
            <contact>
              <ode/>
            </contact>
            <friction>
              <ode/>
              <torsional>
                <ode/>
              </torsional>
            </friction>
            <bounce/>
          </surface>
          <max_contacts>10</max_contacts>
        </collision>
        <visual name='right_outer_knuckle_visual'>
          <pose>0 0 0 0 -0 0</pose>
          <geometry>
            <mesh>
              <scale>1 1 1</scale>
              <uri>/home/snehith/catkin_ws/src/xarm_ros_mod/xarm_gripper/meshes/right_outer_knuckle.STL</uri>
            </mesh>
          </geometry>
        </visual>
        <self_collide>0</self_collide>
        <enable_wind>0</enable_wind>
        <kinematic>0</kinematic>
      </link>
      <joint name='right_finger_joint' type='revolute'>
        <pose relative_to='right_outer_knuckle'>0 -0.035465 0.042039 0 -0 0</pose>
        <parent>right_outer_knuckle</parent>
        <child>right_finger</child>
        <axis>
          <xyz>1 0 0</xyz>
          <limit>
            <lower>0</lower>
            <upper>0.85</upper>
            <effort>50</effort>
            <velocity>2</velocity>
          </limit>
          <dynamics>
            <spring_reference>0</spring_reference>
            <spring_stiffness>0</spring_stiffness>
          </dynamics>
        </axis>
      </joint>
      <link name='right_finger'>
        <pose relative_to='right_finger_joint'>0 0 0 0 -0 0</pose>
        <inertial>
          <pose>0 0.016413 0.029258 0 -0 0</pose>
          <mass>0.048304</mass>
          <inertia>
            <ixx>1.7493e-05</ixx>
            <ixy>-5.0014e-19</ixy>
            <ixz>-7.5079e-18</ixz>
            <iyy>1.7225e-05</iyy>
            <iyz>-4.6435e-06</iyz>
            <izz>5.1466e-06</izz>
          </inertia>
        </inertial>
        <collision name='right_finger_collision'>
          <pose>0 0 0 0 -0 0</pose>
          <geometry>
            <mesh>
              <scale>1 1 1</scale>
              <uri>/home/snehith/catkin_ws/src/xarm_ros_mod/xarm_gripper/meshes/right_finger.STL</uri>
            </mesh>
          </geometry>
          <surface>
            <contact>
              <ode/>
            </contact>
            <friction>
              <ode/>
              <torsional>
                <ode/>
              </torsional>
            </friction>
            <bounce/>
          </surface>
          <max_contacts>10</max_contacts>
        </collision>
        <visual name='right_finger_visual'>
          <pose>0 0 0 0 -0 0</pose>
          <geometry>
            <mesh>
              <scale>1 1 1</scale>
              <uri>/home/snehith/catkin_ws/src/xarm_ros_mod/xarm_gripper/meshes/right_finger.STL</uri>
            </mesh>
          </geometry>
        </visual>
        <self_collide>0</self_collide>
        <enable_wind>0</enable_wind>
        <kinematic>0</kinematic>
      </link>
      <plugin name='gazebo_ros_control' filename='libgazebo_ros_control.so'>
        <robotNamespace>/xarm</robotNamespace>
        <robotSimType>gazebo_ros_control/DefaultRobotHWSim</robotSimType>
        <legacyModeNS>1</legacyModeNS>
      </plugin>
      <plugin name='gazebo_grasp_fix' filename='libgazebo_grasp_fix.so'>
        <arm>
          <arm_name>xarm_gripper</arm_name>
          <palm_link>link6</palm_link>
          <gripper_link>left_inner_knuckle</gripper_link>
          <gripper_link>right_inner_knuckle</gripper_link>
          <gripper_link>left_finger</gripper_link>
          <gripper_link>right_finger</gripper_link>
        </arm>
        <forces_angle_tolerance>100</forces_angle_tolerance>
        <update_rate>10</update_rate>
        <grip_count_threshold>2</grip_count_threshold>
        <max_grip_count>3</max_grip_count>
        <release_tolerance>0.0198</release_tolerance>
        <disable_collisions_on_attach>0</disable_collisions_on_attach>
        <contact_topic>__default_topic__</contact_topic>
        <robotNamespace>/</robotNamespace>
      </plugin>
      <plugin name='left_finger_jointmimic_joint_plugin' filename='libroboticsgroup_upatras_gazebo_mimic_joint_plugin.so'>
        <joint>drive_joint</joint>
        <mimicJoint>left_finger_joint</mimicJoint>
        <multiplier>1.0</multiplier>
        <offset>0</offset>
        <sensitiveness>0.0</sensitiveness>
        <maxEffort>10.0</maxEffort>
        <robotNamespace>/</robotNamespace>
      </plugin>
      <plugin name='left_inner_knuckle_jointmimic_joint_plugin' filename='libroboticsgroup_upatras_gazebo_mimic_joint_plugin.so'>
        <joint>drive_joint</joint>
        <mimicJoint>left_inner_knuckle_joint</mimicJoint>
        <multiplier>1.0</multiplier>
        <offset>0</offset>
        <sensitiveness>0.0</sensitiveness>
        <maxEffort>10.0</maxEffort>
        <robotNamespace>/</robotNamespace>
      </plugin>
      <plugin name='right_outer_knuckle_jointmimic_joint_plugin' filename='libroboticsgroup_upatras_gazebo_mimic_joint_plugin.so'>
        <joint>drive_joint</joint>
        <mimicJoint>right_outer_knuckle_joint</mimicJoint>
        <multiplier>1.0</multiplier>
        <offset>0</offset>
        <sensitiveness>0.0</sensitiveness>
        <maxEffort>10.0</maxEffort>
        <robotNamespace>/</robotNamespace>
      </plugin>
      <plugin name='right_finger_jointmimic_joint_plugin' filename='libroboticsgroup_upatras_gazebo_mimic_joint_plugin.so'>
        <joint>drive_joint</joint>
        <mimicJoint>right_finger_joint</mimicJoint>
        <multiplier>1.0</multiplier>
        <offset>0</offset>
        <sensitiveness>0.0</sensitiveness>
        <maxEffort>10.0</maxEffort>
        <robotNamespace>/</robotNamespace>
      </plugin>
      <static>0</static>
      <plugin name='right_inner_knuckle_jointmimic_joint_plugin' filename='libroboticsgroup_upatras_gazebo_mimic_joint_plugin.so'>
        <joint>drive_joint</joint>
        <mimicJoint>right_inner_knuckle_joint</mimicJoint>
        <multiplier>1.0</multiplier>
        <offset>0</offset>
        <sensitiveness>0.0</sensitiveness>
        <maxEffort>10.0</maxEffort>
        <robotNamespace>/</robotNamespace>
      </plugin>
      <pose>0 0 0.775 0 -0 0</pose>
    </model>
    <state world_name='default'>
      <sim_time>2115 201000000</sim_time>
      <real_time>307 796406499</real_time>
      <wall_time>1675059803 161778992</wall_time>
      <iterations>134778</iterations>
      <model name='bowl'>
        <pose>0.411734 -0.297693 0.80881 1.33122 1.17177 1.30889</pose>
        <scale>1 1 1</scale>
        <link name='body'>
          <pose>0.411734 -0.297693 0.80881 1.33122 1.17177 1.30889</pose>
          <velocity>0 0 0 0 -0 0</velocity>
          <acceleration>0 0 0 0 -0 0</acceleration>
          <wrench>0 0 0 0 -0 0</wrench>
        </link>
      </model>
      <model name='cafe_table'>
        <pose>0.003249 -0.029346 -0.002919 0 -0 0</pose>
        <scale>1 1 1</scale>
        <link name='cafe_table::link'>
          <pose>0.703249 -0.029346 -0.002919 0 -0 0</pose>
          <velocity>0 0 0 0 -0 0</velocity>
          <acceleration>0 0 0 0 -0 0</acceleration>
          <wrench>0 0 0 0 -0 0</wrench>
        </link>
      </model>
      <model name='ground_plane'>
        <pose>0 0 0 0 -0 0</pose>
        <scale>1 1 1</scale>
        <link name='link'>
          <pose>0 0 0 0 -0 0</pose>
          <velocity>0 0 0 0 -0 0</velocity>
          <acceleration>0 0 0 0 -0 0</acceleration>
          <wrench>0 0 0 0 -0 0</wrench>
        </link>
      </model>
      <model name='spoon_plus_aruco'>
        <pose>1.24932 0.598526 -1.31932e+06 0 0.012822 0</pose>
        <scale>1 1 1</scale>
        <link name='body'>
          <pose>0.353232 0.08628 -1.31932e+06 1.51369 0.012822 0</pose>
          <velocity>0 0 -5087.74 0 -0 0</velocity>
          <acceleration>0 0 -9.81 0 -0 0</acceleration>
          <wrench>0 0 -0.13734 0 -0 0</wrench>
        </link>
        <link name='pic1::link'>
          <pose>0.582242 0.064474 -1.31932e+06 0 1.34569 0</pose>
          <velocity>0 0 -5087.74 0 -0 0</velocity>
          <acceleration>0 0 -9.81 0 -0 0</acceleration>
          <wrench>0 0 -9.81 0 -0 0</wrench>
        </link>
      </model>
      <model name='spoon_plus_aruco_0'>
        <pose>1.27254 0.870601 -1.31932e+06 0 -0.067136 0</pose>
        <scale>1 1 1</scale>
        <link name='body'>
          <pose>0.306443 0.358355 -1.31932e+06 1.51369 -0.067136 0</pose>
          <velocity>0 0 -5087.74 0 -0 0</velocity>
          <acceleration>0 0 -9.81 0 -0 0</acceleration>
          <wrench>0 0 -0.13734 0 -0 0</wrench>
        </link>
        <link name='pic1::link'>
          <pose>0.528614 0.336549 -1.31932e+06 0 1.26573 0</pose>
          <velocity>0 0 -5087.74 0 -0 0</velocity>
          <acceleration>0 0 -9.81 0 -0 0</acceleration>
          <wrench>0 0 -9.81 0 -0 0</wrench>
        </link>
      </model>
      <model name='spoon_plus_aruco_1'>
        <pose>1.23713 0.57379 -0.048837 0.024054 -0.016199 0.004415</pose>
        <scale>1 1 1</scale>
        <link name='body'>
          <pose>0.317508 0.035962 0.824499 1.53774 -0.016199 0.004415</pose>
          <velocity>9e-05 0.000694 -0.009258 -0.013222 0.001693 1.6e-05</velocity>
          <acceleration>0 0 -9.81 0 -0 0</acceleration>
          <wrench>0 0 -2.3544 0 -0 0</wrench>
        </link>
        <link name='pic1::link'>
          <pose>0.544314 0.013254 0.907031 0.095396 1.31556 0.097128</pose>
          <velocity>0.00023 0.001789 -0.009341 -0.013222 0.001693 1.6e-05</velocity>
          <acceleration>-0 -1e-06 -9.81001 0 -0 0</acceleration>
          <wrench>-0 -0 -0.00981 0 -0 0</wrench>
        </link>
      </model>
      <model name='spoon_plus_aruco_2'>
        <pose>1.20988 0.854548 -0.055123 0.021973 -1e-06 -0.000451</pose>
        <scale>1 1 1</scale>
        <link name='body'>
          <pose>0.30192 0.323045 0.834142 1.53566 -1e-06 -0.000451</pose>
          <velocity>-1e-06 -0.004812 -0.014142 0.077512 -1e-05 -3e-06</velocity>
          <acceleration>-2e-06 -1e-06 -9.80999 0 -0.001728 -8e-06</acceleration>
          <wrench>-0 -0 -2.3544 0 -0 0</wrench>
        </link>
        <link name='pic1::link'>
          <pose>0.52992 0.299397 0.91304 0.092974 1.33188 0.089897</pose>
          <velocity>-1e-06 -0.010928 -0.015973 0.077512 -8e-06 -3e-06</velocity>
          <acceleration>0.000499 0.000143 -9.81144 -1e-06 0.001728 8e-06</acceleration>
          <wrench>0 0 -0.009811 0 -0 0</wrench>
        </link>
      </model>
      <model name='standard_bowl'>
        <pose>0.372133 0.009058 0.755333 1.57787 -0 0</pose>
        <scale>1 1 1</scale>
        <link name='body'>
          <pose>0.372133 0.009058 0.755333 1.57787 -0 0</pose>
          <velocity>0 0 0 0 -0 0</velocity>
          <acceleration>0 0 0 0 -0 0</acceleration>
          <wrench>0 0 0 0 -0 0</wrench>
        </link>
      </model>
      <model name='standard_bowl_0'>
        <pose>0.368619 0.300714 0.778845 1.5737 -0 0</pose>
        <scale>1 1 1</scale>
        <link name='body'>
          <pose>0.368619 0.300714 0.778845 1.5737 -0 0</pose>
          <velocity>0 0 0 0 -0 0</velocity>
          <acceleration>0 0 0 0 -0 0</acceleration>
          <wrench>0 0 0 0 -0 0</wrench>
        </link>
      </model>
      <model name='xarm6'>
        <pose>0 -0 0.775 -1e-06 -0 -0</pose>
        <scale>1 1 1</scale>
        <link name='left_finger'>
          <pose>0.20731 -0.070213 0.785847 3.14158 -0.00011 0.004092</pose>
          <velocity>-0.002991 -0.003427 -0.000704 -0.039163 0.006265 -0.008254</velocity>
          <acceleration>-2.27341 -8.43696 2.52891 0.991974 0.653938 -0.126758</acceleration>
          <wrench>-0.109815 -0.407539 0.122156 0 -0 0</wrench>
        </link>
        <link name='left_inner_knuckle'>
          <pose>0.207101 -0.019767 0.812901 -3.14112 -0.00013 0.00409</pose>
          <velocity>-0.002564 -0.001617 -0.002112 -0.005955 0.011221 -0.002031</velocity>
          <acceleration>-0.202595 0.506347 0.074905 -0.379228 0.171913 -0.293066</acceleration>
          <wrench>-0.004662 0.011652 0.001724 0 -0 0</wrench>
        </link>
        <link name='left_outer_knuckle'>
          <pose>0.207161 -0.034766 0.827899 -3.14115 -0.000111 0.004092</pose>
          <velocity>-0.002397 -0.001944 -0.001578 -0.041021 0.002755 -0.009296</velocity>
          <acceleration>-0.35879 -1.55173 2.68839 1.02724 -0.798624 3.02126</acceleration>
          <wrench>-0.012062 -0.052166 0.090378 0 -0 0</wrench>
        </link>
        <link name='link1'>
          <pose>-0 0 1.042 -3e-06 -1.2e-05 0.000592</pose>
          <velocity>1.4e-05 -2.8e-05 -4e-05 0.000406 -0.000888 0.000526</velocity>
          <acceleration>0.064583 0.02155 0.154019 -0.838759 0.20504 1.08506</acceleration>
          <wrench>0.139499 0.046548 0.332682 0 -0 0</wrench>
        </link>
        <link name='link2'>
          <pose>2e-06 -0 1.042 -1.57079 4.6e-05 0.000581</pose>
          <velocity>0.000126 4e-05 -8.8e-05 -0.000782 0.008691 -0.000849</velocity>
          <acceleration>-0.139735 -1.02458 0.426604 2.82255 -1.19467 -2.40621</acceleration>
          <wrench>-0.238948 -1.75204 0.729492 0 -0 0</wrench>
        </link>
        <link name='link3'>
          <pose>0.053514 3e-05 1.3265 -1.57079 4.8e-05 0.000594</pose>
          <velocity>0.002512 -0.000188 -0.000719 -0.000405 0.00867 -1.3e-05</velocity>
          <acceleration>-0.207078 -1.32068 0.401231 -0.055625 1.4686 1.34203</acceleration>
          <wrench>-0.286595 -1.82782 0.555303 0 -0 0</wrench>
        </link>
        <link name='link4'>
          <pose>0.130997 8e-05 0.983992 -3.14158 6e-05 0.00193</pose>
          <velocity>-0.00061 -0.000448 -0.001371 -0.001691 0.009386 -0.001476</velocity>
          <acceleration>-0.178447 -0.829984 0.28242 3.06298 -0.288833 -1.92167</acceleration>
          <wrench>-0.198968 -0.925432 0.314898 0 -0 0</wrench>
        </link>
        <link name='link5'>
          <pose>0.130997 8.1e-05 0.98399 -1.57079 -0.000142 0.001938</pose>
          <velocity>-0.000611 -0.000637 -0.001413 -0.001526 0.010696 -0.002533</velocity>
          <acceleration>-0.141753 -0.638461 0.419978 -2.74734 0.890011 -1.17128</acceleration>
          <wrench>-0.180735 -0.814037 0.535472 0 -0 0</wrench>
        </link>
        <link name='link6'>
          <pose>0.20701 0.000231 0.887001 -3.14157 -0.000136 0.004085</pose>
          <velocity>-0.001679 -0.001222 -0.002229 -0.004575 0.010656 -0.002448</velocity>
          <acceleration>-0.170955 0.012957 0.421125 -0.461835 -0.02669 -2.83801</acceleration>
          <wrench>-0.111319 0.008437 0.27422 0 -0 0</wrench>
        </link>
        <link name='link_base'>
          <pose>0 -0 0.775 -1e-06 -0 -0</pose>
          <velocity>-1e-06 1e-06 9e-06 3.4e-05 -7e-06 -2.4e-05</velocity>
          <acceleration>0.002211 -0.000913 0.016014 -0.107563 0.011918 -0.044896</acceleration>
          <wrench>0.006411 -0.002647 0.04644 0 -0 0</wrench>
        </link>
        <link name='right_finger'>
          <pose>0.206735 0.070678 0.785848 -3.14157 -0.000132 0.004101</pose>
          <velocity>-0.00266 -0.001517 -0.002452 -0.00413 0.014588 -0.005252</velocity>
          <acceleration>-1.31958 0.957621 0.943758 -0.324693 0.540514 -1.88394</acceleration>
          <wrench>-0.063741 0.046257 0.045587 0 -0 0</wrench>
        </link>
        <link name='right_inner_knuckle'>
          <pose>0.206938 0.020232 0.812903 3.14116 -0.00013 0.004082</pose>
          <velocity>-0.002443 -0.001613 -0.002391 -0.00396 0.010894 -0.002623</velocity>
          <acceleration>-0.197635 0.490757 0.801929 -0.737461 0.439253 -0.548742</acceleration>
          <wrench>-0.004548 0.011294 0.018455 0 -0 0</wrench>
        </link>
        <link name='right_outer_knuckle'>
          <pose>0.206875 0.035232 0.827903 3.14116 -0.000108 0.004081</pose>
          <velocity>-0.002255 -0.001452 -0.002301 -0.003941 0.010804 -0.002835</velocity>
          <acceleration>-0.220266 0.342008 0.977817 0.677925 -0.386288 1.44836</acceleration>
          <wrench>-0.007405 0.011498 0.032872 0 -0 0</wrench>
        </link>
      </model>
      <model name='xarm_base'>
        <pose>0 0 0 0 -0 0</pose>
        <scale>1 1 1</scale>
        <link name='leg1'>
          <pose>0.1 0.1 0.285 0 -0 0</pose>
          <velocity>0 0 0 0 -0 0</velocity>
          <acceleration>0 0 0 0 -0 0</acceleration>
          <wrench>0 0 0 0 -0 0</wrench>
        </link>
        <link name='leg2'>
          <pose>-0.1 0.1 0.285 0 -0 0</pose>
          <velocity>0 0 0 0 -0 0</velocity>
          <acceleration>0 0 0 0 -0 0</acceleration>
          <wrench>0 0 0 0 -0 0</wrench>
        </link>
        <link name='leg3'>
          <pose>0.1 -0.1 0.285 0 -0 0</pose>
          <velocity>0 0 0 0 -0 0</velocity>
          <acceleration>0 0 0 0 -0 0</acceleration>
          <wrench>0 0 0 0 -0 0</wrench>
        </link>
        <link name='leg4'>
          <pose>-0.1 -0.1 0.285 0 -0 0</pose>
          <velocity>0 0 0 0 -0 0</velocity>
          <acceleration>0 0 0 0 -0 0</acceleration>
          <wrench>0 0 0 0 -0 0</wrench>
        </link>
        <link name='top_plate'>
          <pose>0 0 0.755 0 -0 0</pose>
          <velocity>0 0 0 0 -0 0</velocity>
          <acceleration>0 0 0 0 -0 0</acceleration>
          <wrench>0 0 0 0 -0 0</wrench>
        </link>
      </model>
      <light name='sun'>
        <pose>0 0 10 0 -0 0</pose>
      </light>
    </state>
    <model name='bowl'>
      <static>1</static>
      <link name='body'>
        <visual name='visual'>
          <geometry>
            <mesh>
              <uri>model://bowl/meshes/poly.dae</uri>
            </mesh>
          </geometry>
        </visual>
        <inertial>
          <mass>0.024</mass>
        </inertial>
        <self_collide>0</self_collide>
        <enable_wind>0</enable_wind>
        <kinematic>0</kinematic>
      </link>
      <pose>0.232873 -0.364585 0 0 -0 0</pose>
    </model>
    <model name='standard_bowl'>
      <static>1</static>
      <link name='body'>
        <visual name='visual'>
          <geometry>
            <mesh>
              <uri>model://standard_bowl/meshes/standard_bowl.dae</uri>
            </mesh>
          </geometry>
        </visual>
        <inertial>
          <mass>0.024</mass>
        </inertial>
        <self_collide>0</self_collide>
        <enable_wind>0</enable_wind>
        <kinematic>0</kinematic>
      </link>
      <pose>2.03916 -0.178682 0 0 -0 0</pose>
    </model>
    <model name='spoon_plus_aruco'>
      <static>0</static>
      <link name='body'>
        <inertial>
          <mass>0.014</mass>
          <pose>0 0 0 0 -0 0</pose>
          <inertia>
            <ixx>1</ixx>
            <ixy>0</ixy>
            <ixz>0</ixz>
            <iyy>1</iyy>
            <iyz>0</iyz>
            <izz>1</izz>
          </inertia>
        </inertial>
        <self_collide>0</self_collide>
        <enable_wind>0</enable_wind>
        <kinematic>0</kinematic>
        <pose>-0.907715 -0.512246 0.900738 1.51369 -0 0</pose>
        <gravity>1</gravity>
        <visual name='visual'>
          <geometry>
            <mesh>
              <uri>model://spoon/meshes/Spoon.dae</uri>
              <scale>0.0016 0.0016 0.0016</scale>
            </mesh>
          </geometry>
          <pose>0 0 0 0 -0 0</pose>
          <transparency>0</transparency>
          <cast_shadows>1</cast_shadows>
          <material>
            <shader type='pixel'/>
          </material>
        </visual>
      </link>
      <link name='pic1::link'>
        <pose>-0.679704 -0.534052 0.980134 0 1.33287 0</pose>
        <self_collide>0</self_collide>
        <enable_wind>0</enable_wind>
        <kinematic>0</kinematic>
        <gravity>1</gravity>
        <inertial>
          <mass>0.001</mass>
          <pose>0 0 0 0 -0 0</pose>
          <inertia>
            <ixx>1</ixx>
            <ixy>0</ixy>
            <ixz>0</ixz>
            <iyy>1</iyy>
            <iyz>0</iyz>
            <izz>1</izz>
          </inertia>
        </inertial>
        <visual name='visual'>
          <geometry>
            <mesh>
              <uri>model://pic1/meshes/pic1.dae</uri>
              <scale>0.16 0.16 0.16</scale>
            </mesh>
          </geometry>
          <pose>0 0 0 0 -0 0</pose>
          <transparency>0</transparency>
          <cast_shadows>1</cast_shadows>
          <material>
            <shader type='pixel'/>
          </material>
        </visual>
      </link>
      <static>1</static>
      <allow_auto_disable>1</allow_auto_disable>
      <pose>1.25013 0.681904 0 0 -0 0</pose>
    </model>
    <model name='standard_bowl_0'>
      <static>1</static>
      <link name='body'>
        <visual name='visual'>
          <geometry>
            <mesh>
              <uri>model://standard_bowl/meshes/standard_bowl.dae</uri>
            </mesh>
          </geometry>
        </visual>
        <inertial>
          <mass>0.024</mass>
        </inertial>
        <self_collide>0</self_collide>
        <enable_wind>0</enable_wind>
        <kinematic>0</kinematic>
      </link>
      <pose>1.23214 -0.055267 0 0 -0 0</pose>
    </model>
    <model name='spoon_plus_aruco_0'>
      <static>0</static>
      <link name='body'>
        <inertial>
          <mass>0.014</mass>
          <pose>0 0 0 0 -0 0</pose>
          <inertia>
            <ixx>1</ixx>
            <ixy>0</ixy>
            <ixz>0</ixz>
            <iyy>1</iyy>
            <iyz>0</iyz>
            <izz>1</izz>
          </inertia>
        </inertial>
        <self_collide>0</self_collide>
        <enable_wind>0</enable_wind>
        <kinematic>0</kinematic>
        <pose>-0.907715 -0.512246 0.900738 1.51369 -0 0</pose>
        <gravity>1</gravity>
        <visual name='visual'>
          <geometry>
            <mesh>
              <uri>model://spoon/meshes/Spoon.dae</uri>
              <scale>0.0016 0.0016 0.0016</scale>
            </mesh>
          </geometry>
          <pose>0 0 0 0 -0 0</pose>
          <transparency>0</transparency>
          <cast_shadows>1</cast_shadows>
          <material>
            <shader type='pixel'/>
          </material>
        </visual>
      </link>
      <link name='pic1::link'>
        <pose>-0.679704 -0.534052 0.980134 0 1.33287 0</pose>
        <self_collide>0</self_collide>
        <enable_wind>0</enable_wind>
        <kinematic>0</kinematic>
        <gravity>1</gravity>
        <inertial>
          <mass>0.001</mass>
          <pose>0 0 0 0 -0 0</pose>
          <inertia>
            <ixx>1</ixx>
            <ixy>0</ixy>
            <ixz>0</ixz>
            <iyy>1</iyy>
            <iyz>0</iyz>
            <izz>1</izz>
          </inertia>
        </inertial>
        <visual name='visual'>
          <geometry>
            <mesh>
              <uri>model://pic1/meshes/pic1.dae</uri>
              <scale>0.16 0.16 0.16</scale>
            </mesh>
          </geometry>
          <pose>0 0 0 0 -0 0</pose>
          <transparency>0</transparency>
          <cast_shadows>1</cast_shadows>
          <material>
            <shader type='pixel'/>
          </material>
        </visual>
      </link>
      <static>1</static>
      <allow_auto_disable>1</allow_auto_disable>
      <pose>1.27254 0.870601 0 0 -0 0</pose>
    </model>
    <model name='spoon_plus_aruco_1'>
      <static>0</static>
      <link name='body'>
        <collision name='collision'>
          <geometry>
            <box>
              <size>0.1 0.1 0.1</size>
            </box>
          </geometry>
          <max_contacts>10</max_contacts>
          <surface>
            <contact>
              <ode/>
            </contact>
            <bounce/>
            <friction>
              <torsional>
                <ode/>
              </torsional>
              <ode/>
            </friction>
          </surface>
        </collision>
        <inertial>
          <mass>0.24</mass>
          <pose>0 0 0 0 -0 0</pose>
          <inertia>
            <ixx>1</ixx>
            <ixy>0</ixy>
            <ixz>0</ixz>
            <iyy>1</iyy>
            <iyz>0</iyz>
            <izz>1</izz>
          </inertia>
        </inertial>
        <self_collide>0</self_collide>
        <enable_wind>0</enable_wind>
        <kinematic>0</kinematic>
        <pose>-0.907715 -0.512246 0.900738 1.51369 -0 0</pose>
        <gravity>1</gravity>
        <visual name='visual'>
          <geometry>
            <mesh>
              <uri>model://spoon/meshes/Spoon.dae</uri>
              <scale>0.0016 0.0016 0.0016</scale>
            </mesh>
          </geometry>
          <pose>0 0 0 0 -0 0</pose>
          <transparency>0</transparency>
          <cast_shadows>1</cast_shadows>
          <material>
            <shader type='pixel'/>
          </material>
        </visual>
      </link>
      <link name='pic1::link'>
        <pose>-0.679704 -0.534052 0.980134 0 1.33287 0</pose>
        <self_collide>0</self_collide>
        <enable_wind>0</enable_wind>
        <kinematic>0</kinematic>
        <gravity>1</gravity>
        <inertial>
          <mass>0.001</mass>
          <pose>0 0 0 0 -0 0</pose>
          <inertia>
            <ixx>1</ixx>
            <ixy>0</ixy>
            <ixz>0</ixz>
            <iyy>1</iyy>
            <iyz>0</iyz>
            <izz>1</izz>
          </inertia>
        </inertial>
        <visual name='visual'>
          <geometry>
            <mesh>
              <uri>model://pic1/meshes/pic1.dae</uri>
              <scale>0.16 0.16 0.16</scale>
            </mesh>
          </geometry>
          <pose>0 0 0 0 -0 0</pose>
          <transparency>0</transparency>
          <cast_shadows>1</cast_shadows>
          <material>
            <shader type='pixel'/>
          </material>
        </visual>
      </link>
      <joint name='aruco_joint' type='fixed'>
        <child>pic1::link</child>
        <parent>body</parent>
      </joint>
      <pose>1.32932 0.548699 0 0 -0 0</pose>
    </model>
    <model name='spoon_plus_aruco_2'>
      <static>0</static>
      <link name='body'>
        <collision name='collision'>
          <geometry>
            <box>
              <size>0.12 0.12 0.12</size>
            </box>
          </geometry>
          <max_contacts>10</max_contacts>
          <surface>
            <contact>
              <ode/>
            </contact>
            <bounce/>
            <friction>
              <torsional>
                <ode/>
              </torsional>
              <ode/>
            </friction>
          </surface>
        </collision>
        <inertial>
          <mass>0.24</mass>
          <pose>0 0 0 0 -0 0</pose>
          <inertia>
            <ixx>1</ixx>
            <ixy>0</ixy>
            <ixz>0</ixz>
            <iyy>1</iyy>
            <iyz>0</iyz>
            <izz>1</izz>
          </inertia>
        </inertial>
        <self_collide>0</self_collide>
        <enable_wind>0</enable_wind>
        <kinematic>0</kinematic>
        <pose>-0.907715 -0.512246 0.900738 1.51369 -0 0</pose>
        <gravity>1</gravity>
        <visual name='visual'>
          <geometry>
            <mesh>
              <uri>model://spoon/meshes/Spoon.dae</uri>
              <scale>0.0016 0.0016 0.0016</scale>
            </mesh>
          </geometry>
          <pose>0 0 0 0 -0 0</pose>
          <transparency>0</transparency>
          <cast_shadows>1</cast_shadows>
          <material>
            <shader type='pixel'/>
          </material>
        </visual>
      </link>
      <link name='pic1::link'>
        <pose>-0.679704 -0.534052 0.980134 0 1.33287 0</pose>
        <self_collide>0</self_collide>
        <enable_wind>0</enable_wind>
        <kinematic>0</kinematic>
        <gravity>1</gravity>
        <inertial>
          <mass>0.001</mass>
          <pose>0 0 0 0 -0 0</pose>
          <inertia>
            <ixx>1</ixx>
            <ixy>0</ixy>
            <ixz>0</ixz>
            <iyy>1</iyy>
            <iyz>0</iyz>
            <izz>1</izz>
          </inertia>
        </inertial>
        <visual name='visual'>
          <geometry>
            <mesh>
              <uri>model://pic1/meshes/pic1.dae</uri>
              <scale>0.16 0.16 0.16</scale>
            </mesh>
          </geometry>
          <pose>0 0 0 0 -0 0</pose>
          <transparency>0</transparency>
          <cast_shadows>1</cast_shadows>
          <material>
            <shader type='pixel'/>
          </material>
        </visual>
      </link>
      <joint name='aruco_joint' type='fixed'>
        <child>pic1::link</child>
        <parent>body</parent>
      </joint>
      <pose>1.1745 0.836676 0 0 -0 0</pose>
    </model>
  </world>
</sdf>
